Using MAPPING_STR=22220000, VERSION_DIR=v4_engman
Running /platform/source/s01/v4_engman/m22220000/m22220000_q10_t0.sh
Requirement already satisfied: pymysql in /usr/local/lib/python3.8/dist-packages (1.1.0)
Requirement already satisfied: pandas in /usr/local/lib/python3.8/dist-packages (2.0.3)
Requirement already satisfied: python-dateutil>=2.8.2 in /usr/local/lib/python3.8/dist-packages (from pandas) (2.8.2)
Requirement already satisfied: tzdata>=2022.1 in /usr/local/lib/python3.8/dist-packages (from pandas) (2023.3)
Requirement already satisfied: pytz>=2020.1 in /usr/local/lib/python3.8/dist-packages (from pandas) (2023.3.post1)
Requirement already satisfied: numpy>=1.20.3; python_version < "3.10" in /usr/local/lib/python3.8/dist-packages (from pandas) (1.24.4)
Requirement already satisfied: six>=1.5 in /usr/local/lib/python3.8/dist-packages (from python-dateutil>=2.8.2->pandas) (1.16.0)
Collecting git+https://github.com/tanoabeleyra/direct_redis.git
  Cloning https://github.com/tanoabeleyra/direct_redis.git to /tmp/pip-req-build-ftoblt14
  Running command git clone -q https://github.com/tanoabeleyra/direct_redis.git /tmp/pip-req-build-ftoblt14
[31m  ERROR: Error [Errno 2] No such file or directory: 'git' while executing command git clone -q https://github.com/tanoabeleyra/direct_redis.git /tmp/pip-req-build-ftoblt14[0m
[31mERROR: Cannot find command 'git' - do you have 'git' installed and in your PATH?[0m
Running /platform/source/s01/v4_engman/m22220000/m22220000_q11_t0.sh
Requirement already satisfied: pymysql in /usr/local/lib/python3.8/dist-packages (1.1.0)
Requirement already satisfied: pandas in /usr/local/lib/python3.8/dist-packages (2.0.3)
Requirement already satisfied: python-dateutil>=2.8.2 in /usr/local/lib/python3.8/dist-packages (from pandas) (2.8.2)
Requirement already satisfied: numpy>=1.20.3; python_version < "3.10" in /usr/local/lib/python3.8/dist-packages (from pandas) (1.24.4)
Requirement already satisfied: tzdata>=2022.1 in /usr/local/lib/python3.8/dist-packages (from pandas) (2023.3)
Requirement already satisfied: pytz>=2020.1 in /usr/local/lib/python3.8/dist-packages (from pandas) (2023.3.post1)
Requirement already satisfied: six>=1.5 in /usr/local/lib/python3.8/dist-packages (from python-dateutil>=2.8.2->pandas) (1.16.0)
Requirement already satisfied: direct_redis in /usr/local/lib/python3.8/dist-packages (0.3.1)
Requirement already satisfied: redis==3.4.1 in /usr/local/lib/python3.8/dist-packages (from direct_redis) (3.4.1)
Running /platform/source/s01/v4_engman/m22220000/m22220000_q12_t0.sh
/platform/source/s01/v4_engman/m22220000/m22220000_q12_t0.sh: line 4: sudo: command not found
/platform/source/s01/v4_engman/m22220000/m22220000_q12_t0.sh: line 5: sudo: command not found
/platform/source/s01/v4_engman/m22220000/m22220000_q12_t0.sh: line 8: sudo: command not found
Requirement already satisfied: pymysql in /usr/local/lib/python3.8/dist-packages (1.1.0)
Running /platform/source/s01/v4_engman/m22220000/m22220000_q13_t0.sh
Requirement already satisfied: pymysql in /usr/local/lib/python3.8/dist-packages (1.1.0)
Running /platform/source/s01/v4_engman/m22220000/m22220000_q14_t0.sh
0% [Working]            Hit:1 http://ports.ubuntu.com/ubuntu-ports focal InRelease
0% [Working]0% [Waiting for headers]                        Get:2 http://ports.ubuntu.com/ubuntu-ports focal-updates InRelease [114 kB]
0% [2 InRelease 5631 B/114 kB 5%]                                 0% [Working]            Hit:3 http://ports.ubuntu.com/ubuntu-ports focal-backports InRelease
0% [Working]0% [Waiting for headers]0% [Waiting for headers]                        Hit:4 http://ports.ubuntu.com/ubuntu-ports focal-security InRelease
                        0% [Working]100% [Working]              Fetched 114 kB in 1s (128 kB/s)
Reading package lists... 0%Reading package lists... 0%Reading package lists... 0%Reading package lists... 6%Reading package lists... 6%Reading package lists... 6%Reading package lists... 6%Reading package lists... 60%Reading package lists... 60%Reading package lists... 61%Reading package lists... 61%Reading package lists... 74%Reading package lists... 74%Reading package lists... 75%Reading package lists... 75%Reading package lists... 81%Reading package lists... 81%Reading package lists... 81%Reading package lists... 81%Reading package lists... 82%Reading package lists... 82%Reading package lists... 82%Reading package lists... 82%Reading package lists... 94%Reading package lists... 94%Reading package lists... 94%Reading package lists... 94%Reading package lists... 99%Reading package lists... 99%Reading package lists... 99%Reading package lists... 99%Reading package lists... Done
Reading package lists... 0%Reading package lists... 0%Reading package lists... 0%Reading package lists... 6%Reading package lists... 6%Reading package lists... 6%Reading package lists... 6%Reading package lists... 60%Reading package lists... 60%Reading package lists... 61%Reading package lists... 61%Reading package lists... 74%Reading package lists... 74%Reading package lists... 75%Reading package lists... 75%Reading package lists... 81%Reading package lists... 81%Reading package lists... 81%Reading package lists... 81%Reading package lists... 82%Reading package lists... 82%Reading package lists... 82%Reading package lists... 82%Reading package lists... 94%Reading package lists... 94%Reading package lists... 94%Reading package lists... 94%Reading package lists... 99%Reading package lists... 99%Reading package lists... 99%Reading package lists... 99%Reading package lists... Done
Building dependency tree... 0%Building dependency tree... 0%Building dependency tree... 50%Building dependency tree... 50%Building dependency tree       
Reading state information... 0%Reading state information... 0%Reading state information... Done
python3 is already the newest version (3.8.2-0ubuntu2).
python3 set to manually installed.
python3-pip is already the newest version (20.0.2-5ubuntu1.10).
0 upgraded, 0 newly installed, 0 to remove and 0 not upgraded.
Requirement already satisfied: pymysql in /usr/local/lib/python3.8/dist-packages (1.1.0)
Requirement already satisfied: pandas in /usr/local/lib/python3.8/dist-packages (2.0.3)
Requirement already satisfied: redis in /usr/local/lib/python3.8/dist-packages (3.4.1)
Requirement already satisfied: direct_redis in /usr/local/lib/python3.8/dist-packages (0.3.1)
Requirement already satisfied: numpy>=1.20.3; python_version < "3.10" in /usr/local/lib/python3.8/dist-packages (from pandas) (1.24.4)
Requirement already satisfied: tzdata>=2022.1 in /usr/local/lib/python3.8/dist-packages (from pandas) (2023.3)
Requirement already satisfied: pytz>=2020.1 in /usr/local/lib/python3.8/dist-packages (from pandas) (2023.3.post1)
Requirement already satisfied: python-dateutil>=2.8.2 in /usr/local/lib/python3.8/dist-packages (from pandas) (2.8.2)
Requirement already satisfied: six>=1.5 in /usr/local/lib/python3.8/dist-packages (from python-dateutil>=2.8.2->pandas) (1.16.0)
Running /platform/source/s01/v4_engman/m22220000/m22220000_q15_t0.sh
0% [Working]            Hit:1 http://ports.ubuntu.com/ubuntu-ports focal InRelease
0% [Working]0% [Waiting for headers]                        Hit:2 http://ports.ubuntu.com/ubuntu-ports focal-updates InRelease
                        0% [Working]0% [Waiting for headers]                        Hit:3 http://ports.ubuntu.com/ubuntu-ports focal-backports InRelease
                        0% [Working]0% [Waiting for headers]                        Hit:4 http://ports.ubuntu.com/ubuntu-ports focal-security InRelease
                        0% [Working]20% [Working]             Reading package lists... 0%Reading package lists... 0%Reading package lists... 0%Reading package lists... 6%Reading package lists... 6%Reading package lists... 6%Reading package lists... 6%Reading package lists... 60%Reading package lists... 60%Reading package lists... 61%Reading package lists... 61%Reading package lists... 74%Reading package lists... 74%Reading package lists... 75%Reading package lists... 75%Reading package lists... 81%Reading package lists... 81%Reading package lists... 81%Reading package lists... 81%Reading package lists... 82%Reading package lists... 82%Reading package lists... 82%Reading package lists... 82%Reading package lists... 94%Reading package lists... 94%Reading package lists... 94%Reading package lists... 94%Reading package lists... 99%Reading package lists... 99%Reading package lists... 99%Reading package lists... 99%Reading package lists... Done
Reading package lists... 0%Reading package lists... 0%Reading package lists... 0%Reading package lists... 6%Reading package lists... 6%Reading package lists... 6%Reading package lists... 6%Reading package lists... 60%Reading package lists... 60%Reading package lists... 61%Reading package lists... 61%Reading package lists... 74%Reading package lists... 74%Reading package lists... 75%Reading package lists... 75%Reading package lists... 81%Reading package lists... 81%Reading package lists... 81%Reading package lists... 81%Reading package lists... 82%Reading package lists... 82%Reading package lists... 82%Reading package lists... 82%Reading package lists... 94%Reading package lists... 94%Reading package lists... 94%Reading package lists... 94%Reading package lists... 99%Reading package lists... 99%Reading package lists... 99%Reading package lists... 99%Reading package lists... Done
Building dependency tree... 0%Building dependency tree... 0%Building dependency tree... 50%Building dependency tree... 50%Building dependency tree       
Reading state information... 0%Reading state information... 0%Reading state information... Done
Calculating upgrade... 0%Calculating upgrade... 50%Calculating upgrade... Done
0 upgraded, 0 newly installed, 0 to remove and 0 not upgraded.
Reading package lists... 0%Reading package lists... 0%Reading package lists... 0%Reading package lists... 6%Reading package lists... 6%Reading package lists... 6%Reading package lists... 6%Reading package lists... 60%Reading package lists... 60%Reading package lists... 61%Reading package lists... 61%Reading package lists... 74%Reading package lists... 74%Reading package lists... 75%Reading package lists... 75%Reading package lists... 81%Reading package lists... 81%Reading package lists... 81%Reading package lists... 81%Reading package lists... 82%Reading package lists... 82%Reading package lists... 82%Reading package lists... 82%Reading package lists... 94%Reading package lists... 94%Reading package lists... 94%Reading package lists... 94%Reading package lists... 99%Reading package lists... 99%Reading package lists... 99%Reading package lists... 99%Reading package lists... Done
Building dependency tree... 0%Building dependency tree... 0%Building dependency tree... 50%Building dependency tree... 50%Building dependency tree       
Reading state information... 0%Reading state information... 0%Reading state information... Done
python3 is already the newest version (3.8.2-0ubuntu2).
python3-pip is already the newest version (20.0.2-5ubuntu1.10).
0 upgraded, 0 newly installed, 0 to remove and 0 not upgraded.
Requirement already satisfied: pymysql in /usr/local/lib/python3.8/dist-packages (1.1.0)
Requirement already satisfied: pandas in /usr/local/lib/python3.8/dist-packages (2.0.3)
Requirement already satisfied: direct_redis in /usr/local/lib/python3.8/dist-packages (0.3.1)
Requirement already satisfied: numpy>=1.20.3; python_version < "3.10" in /usr/local/lib/python3.8/dist-packages (from pandas) (1.24.4)
Requirement already satisfied: tzdata>=2022.1 in /usr/local/lib/python3.8/dist-packages (from pandas) (2023.3)
Requirement already satisfied: python-dateutil>=2.8.2 in /usr/local/lib/python3.8/dist-packages (from pandas) (2.8.2)
Requirement already satisfied: pytz>=2020.1 in /usr/local/lib/python3.8/dist-packages (from pandas) (2023.3.post1)
Requirement already satisfied: redis==3.4.1 in /usr/local/lib/python3.8/dist-packages (from direct_redis) (3.4.1)
Requirement already satisfied: six>=1.5 in /usr/local/lib/python3.8/dist-packages (from python-dateutil>=2.8.2->pandas) (1.16.0)
Running /platform/source/s01/v4_engman/m22220000/m22220000_q16_t0.sh
0% [Working]            Hit:1 http://ports.ubuntu.com/ubuntu-ports focal InRelease
0% [Working]0% [Waiting for headers]                        Hit:2 http://ports.ubuntu.com/ubuntu-ports focal-updates InRelease
                        0% [Working]0% [Waiting for headers]                        Hit:3 http://ports.ubuntu.com/ubuntu-ports focal-backports InRelease
                        0% [Working]0% [Waiting for headers]                        Hit:4 http://ports.ubuntu.com/ubuntu-ports focal-security InRelease
                        0% [Working]20% [Working]             Reading package lists... 0%Reading package lists... 0%Reading package lists... 0%Reading package lists... 6%Reading package lists... 6%Reading package lists... 6%Reading package lists... 6%Reading package lists... 60%Reading package lists... 60%Reading package lists... 61%Reading package lists... 61%Reading package lists... 74%Reading package lists... 74%Reading package lists... 75%Reading package lists... 75%Reading package lists... 81%Reading package lists... 81%Reading package lists... 81%Reading package lists... 81%Reading package lists... 82%Reading package lists... 82%Reading package lists... 82%Reading package lists... 82%Reading package lists... 94%Reading package lists... 94%Reading package lists... 94%Reading package lists... 94%Reading package lists... 99%Reading package lists... 99%Reading package lists... 99%Reading package lists... 99%Reading package lists... Done
Reading package lists... 0%Reading package lists... 0%Reading package lists... 0%Reading package lists... 6%Reading package lists... 6%Reading package lists... 6%Reading package lists... 6%Reading package lists... 60%Reading package lists... 60%Reading package lists... 61%Reading package lists... 61%Reading package lists... 74%Reading package lists... 74%Reading package lists... 75%Reading package lists... 75%Reading package lists... 81%Reading package lists... 81%Reading package lists... 81%Reading package lists... 81%Reading package lists... 82%Reading package lists... 82%Reading package lists... 82%Reading package lists... 82%Reading package lists... 94%Reading package lists... 94%Reading package lists... 94%Reading package lists... 94%Reading package lists... 99%Reading package lists... 99%Reading package lists... 99%Reading package lists... 99%Reading package lists... Done
Building dependency tree... 0%Building dependency tree... 0%Building dependency tree... 50%Building dependency tree... 50%Building dependency tree       
Reading state information... 0%Reading state information... 0%Reading state information... Done
python3 is already the newest version (3.8.2-0ubuntu2).
python3-pip is already the newest version (20.0.2-5ubuntu1.10).
0 upgraded, 0 newly installed, 0 to remove and 0 not upgraded.
Requirement already satisfied: pymysql in /usr/local/lib/python3.8/dist-packages (1.1.0)
Requirement already satisfied: pandas in /usr/local/lib/python3.8/dist-packages (2.0.3)
Requirement already satisfied: redis in /usr/local/lib/python3.8/dist-packages (3.4.1)
Requirement already satisfied: direct_redis in /usr/local/lib/python3.8/dist-packages (0.3.1)
Requirement already satisfied: numpy>=1.20.3; python_version < "3.10" in /usr/local/lib/python3.8/dist-packages (from pandas) (1.24.4)
Requirement already satisfied: pytz>=2020.1 in /usr/local/lib/python3.8/dist-packages (from pandas) (2023.3.post1)
Requirement already satisfied: tzdata>=2022.1 in /usr/local/lib/python3.8/dist-packages (from pandas) (2023.3)
Requirement already satisfied: python-dateutil>=2.8.2 in /usr/local/lib/python3.8/dist-packages (from pandas) (2.8.2)
Requirement already satisfied: six>=1.5 in /usr/local/lib/python3.8/dist-packages (from python-dateutil>=2.8.2->pandas) (1.16.0)
Running /platform/source/s01/v4_engman/m22220000/m22220000_q17_t0.sh
/platform/source/s01/v4_engman/m22220000/m22220000_q17_t0.sh: line 4: sudo: command not found
/platform/source/s01/v4_engman/m22220000/m22220000_q17_t0.sh: line 5: sudo: command not found
Requirement already satisfied: pymysql in /usr/local/lib/python3.8/dist-packages (1.1.0)
Requirement already satisfied: pandas in /usr/local/lib/python3.8/dist-packages (2.0.3)
Requirement already satisfied: direct_redis in /usr/local/lib/python3.8/dist-packages (0.3.1)
Requirement already satisfied: python-dateutil>=2.8.2 in /usr/local/lib/python3.8/dist-packages (from pandas) (2.8.2)
Requirement already satisfied: pytz>=2020.1 in /usr/local/lib/python3.8/dist-packages (from pandas) (2023.3.post1)
Requirement already satisfied: tzdata>=2022.1 in /usr/local/lib/python3.8/dist-packages (from pandas) (2023.3)
Requirement already satisfied: numpy>=1.20.3; python_version < "3.10" in /usr/local/lib/python3.8/dist-packages (from pandas) (1.24.4)
Requirement already satisfied: redis==3.4.1 in /usr/local/lib/python3.8/dist-packages (from direct_redis) (3.4.1)
Requirement already satisfied: six>=1.5 in /usr/local/lib/python3.8/dist-packages (from python-dateutil>=2.8.2->pandas) (1.16.0)
Running /platform/source/s01/v4_engman/m22220000/m22220000_q18_t0.sh
Running /platform/source/s01/v4_engman/m22220000/m22220000_q19_t0.sh
/platform/source/s01/v4_engman/m22220000/m22220000_q19_t0.sh: line 4: sudo: command not found
/platform/source/s01/v4_engman/m22220000/m22220000_q19_t0.sh: line 5: sudo: command not found
/platform/source/s01/v4_engman/m22220000/m22220000_q19_t0.sh: line 6: sudo: command not found
Requirement already satisfied: pymysql in /usr/local/lib/python3.8/dist-packages (1.1.0)
Requirement already satisfied: pandas in /usr/local/lib/python3.8/dist-packages (2.0.3)
Requirement already satisfied: numpy>=1.20.3; python_version < "3.10" in /usr/local/lib/python3.8/dist-packages (from pandas) (1.24.4)
Requirement already satisfied: tzdata>=2022.1 in /usr/local/lib/python3.8/dist-packages (from pandas) (2023.3)
Requirement already satisfied: python-dateutil>=2.8.2 in /usr/local/lib/python3.8/dist-packages (from pandas) (2.8.2)
Requirement already satisfied: pytz>=2020.1 in /usr/local/lib/python3.8/dist-packages (from pandas) (2023.3.post1)
Requirement already satisfied: six>=1.5 in /usr/local/lib/python3.8/dist-packages (from python-dateutil>=2.8.2->pandas) (1.16.0)
Requirement already satisfied: direct-redis in /usr/local/lib/python3.8/dist-packages (0.3.1)
Requirement already satisfied: redis==3.4.1 in /usr/local/lib/python3.8/dist-packages (from direct-redis) (3.4.1)
Running /platform/source/s01/v4_engman/m22220000/m22220000_q1_t0.sh
0% [Working]            Hit:1 http://ports.ubuntu.com/ubuntu-ports focal InRelease
0% [Working]0% [Waiting for headers]                        Hit:2 http://ports.ubuntu.com/ubuntu-ports focal-updates InRelease
                        0% [Working]0% [Waiting for headers]                        Hit:3 http://ports.ubuntu.com/ubuntu-ports focal-backports InRelease
                        0% [Working]0% [Waiting for headers]                        Hit:4 http://ports.ubuntu.com/ubuntu-ports focal-security InRelease
                        0% [Working]20% [Working]             Reading package lists... 0%Reading package lists... 0%Reading package lists... 0%Reading package lists... 6%Reading package lists... 6%Reading package lists... 6%Reading package lists... 6%Reading package lists... 60%Reading package lists... 60%Reading package lists... 61%Reading package lists... 61%Reading package lists... 74%Reading package lists... 74%Reading package lists... 75%Reading package lists... 75%Reading package lists... 81%Reading package lists... 81%Reading package lists... 81%Reading package lists... 81%Reading package lists... 82%Reading package lists... 82%Reading package lists... 82%Reading package lists... 82%Reading package lists... 94%Reading package lists... 94%Reading package lists... 94%Reading package lists... 94%Reading package lists... 99%Reading package lists... 99%Reading package lists... 99%Reading package lists... 99%Reading package lists... Done
Requirement already satisfied: pymysql in /usr/local/lib/python3.8/dist-packages (1.1.0)
Running /platform/source/s01/v4_engman/m22220000/m22220000_q20_t0.sh
/platform/source/s01/v4_engman/m22220000/m22220000_q20_t0.sh: line 4: sudo: command not found
/platform/source/s01/v4_engman/m22220000/m22220000_q20_t0.sh: line 7: sudo: command not found
Requirement already satisfied: pymysql in /usr/local/lib/python3.8/dist-packages (1.1.0)
Requirement already satisfied: pandas in /usr/local/lib/python3.8/dist-packages (2.0.3)
Requirement already satisfied: pytz>=2020.1 in /usr/local/lib/python3.8/dist-packages (from pandas) (2023.3.post1)
Requirement already satisfied: tzdata>=2022.1 in /usr/local/lib/python3.8/dist-packages (from pandas) (2023.3)
Requirement already satisfied: numpy>=1.20.3; python_version < "3.10" in /usr/local/lib/python3.8/dist-packages (from pandas) (1.24.4)
Requirement already satisfied: python-dateutil>=2.8.2 in /usr/local/lib/python3.8/dist-packages (from pandas) (2.8.2)
Requirement already satisfied: six>=1.5 in /usr/local/lib/python3.8/dist-packages (from python-dateutil>=2.8.2->pandas) (1.16.0)
/platform/source/s01/v4_engman/m22220000/m22220000_q20_t0.sh: line 13: git: command not found
/platform/source/s01/v4_engman/m22220000/m22220000_q20_t0.sh: line 14: cd: direct_redis: No such file or directory
python3: can't open file 'setup.py': [Errno 2] No such file or directory
python3: can't open file 'query.py': [Errno 2] No such file or directory
Running /platform/source/s01/v4_engman/m22220000/m22220000_q21_t0.sh
0% [Working]            Hit:1 http://ports.ubuntu.com/ubuntu-ports focal InRelease
0% [Working]0% [Waiting for headers]                        Hit:2 http://ports.ubuntu.com/ubuntu-ports focal-updates InRelease
                        0% [Working]0% [Waiting for headers]                        Hit:3 http://ports.ubuntu.com/ubuntu-ports focal-backports InRelease
                        0% [Working]0% [Waiting for headers]                        Hit:4 http://ports.ubuntu.com/ubuntu-ports focal-security InRelease
                        0% [Working]20% [Working]             Reading package lists... 0%Reading package lists... 0%Reading package lists... 0%Reading package lists... 6%Reading package lists... 6%Reading package lists... 6%Reading package lists... 6%Reading package lists... 60%Reading package lists... 60%Reading package lists... 61%Reading package lists... 61%Reading package lists... 74%Reading package lists... 74%Reading package lists... 75%Reading package lists... 75%Reading package lists... 81%Reading package lists... 81%Reading package lists... 81%Reading package lists... 81%Reading package lists... 82%Reading package lists... 82%Reading package lists... 82%Reading package lists... 82%Reading package lists... 94%Reading package lists... 94%Reading package lists... 94%Reading package lists... 94%Reading package lists... 99%Reading package lists... 99%Reading package lists... 99%Reading package lists... 99%Reading package lists... Done
Requirement already satisfied: pymysql in /usr/local/lib/python3.8/dist-packages (1.1.0)
Requirement already satisfied: direct_redis in /usr/local/lib/python3.8/dist-packages (0.3.1)
Requirement already satisfied: redis==3.4.1 in /usr/local/lib/python3.8/dist-packages (from direct_redis) (3.4.1)
Requirement already satisfied: pandas in /usr/local/lib/python3.8/dist-packages (2.0.3)
Requirement already satisfied: numpy>=1.20.3; python_version < "3.10" in /usr/local/lib/python3.8/dist-packages (from pandas) (1.24.4)
Requirement already satisfied: pytz>=2020.1 in /usr/local/lib/python3.8/dist-packages (from pandas) (2023.3.post1)
Requirement already satisfied: python-dateutil>=2.8.2 in /usr/local/lib/python3.8/dist-packages (from pandas) (2.8.2)
Requirement already satisfied: tzdata>=2022.1 in /usr/local/lib/python3.8/dist-packages (from pandas) (2023.3)
Requirement already satisfied: six>=1.5 in /usr/local/lib/python3.8/dist-packages (from python-dateutil>=2.8.2->pandas) (1.16.0)
Running /platform/source/s01/v4_engman/m22220000/m22220000_q22_t0.sh
/platform/source/s01/v4_engman/m22220000/m22220000_q22_t0.sh: line 4: sudo: command not found
/platform/source/s01/v4_engman/m22220000/m22220000_q22_t0.sh: line 7: sudo: command not found
Requirement already satisfied: pymysql in /usr/local/lib/python3.8/dist-packages (1.1.0)
Running /platform/source/s01/v4_engman/m22220000/m22220000_q2_t0.sh
Requirement already satisfied: pymysql in /usr/local/lib/python3.8/dist-packages (1.1.0)
Requirement already satisfied: pandas in /usr/local/lib/python3.8/dist-packages (2.0.3)
Requirement already satisfied: python-dateutil>=2.8.2 in /usr/local/lib/python3.8/dist-packages (from pandas) (2.8.2)
Requirement already satisfied: pytz>=2020.1 in /usr/local/lib/python3.8/dist-packages (from pandas) (2023.3.post1)
Requirement already satisfied: tzdata>=2022.1 in /usr/local/lib/python3.8/dist-packages (from pandas) (2023.3)
Requirement already satisfied: numpy>=1.20.3; python_version < "3.10" in /usr/local/lib/python3.8/dist-packages (from pandas) (1.24.4)
Requirement already satisfied: six>=1.5 in /usr/local/lib/python3.8/dist-packages (from python-dateutil>=2.8.2->pandas) (1.16.0)
[31mERROR: Could not find a version that satisfies the requirement redis-direct (from versions: none)[0m
[31mERROR: No matching distribution found for redis-direct[0m
Running /platform/source/s01/v4_engman/m22220000/m22220000_q3_t0.sh
/platform/source/s01/v4_engman/m22220000/m22220000_q3_t0.sh: line 4: sudo: command not found
/platform/source/s01/v4_engman/m22220000/m22220000_q3_t0.sh: line 5: sudo: command not found
/platform/source/s01/v4_engman/m22220000/m22220000_q3_t0.sh: line 6: sudo: command not found
Requirement already satisfied: pymysql in /usr/local/lib/python3.8/dist-packages (1.1.0)
Running /platform/source/s01/v4_engman/m22220000/m22220000_q4_t0.sh
/platform/source/s01/v4_engman/m22220000/m22220000_q4_t0.sh: line 5: sudo: command not found
/platform/source/s01/v4_engman/m22220000/m22220000_q4_t0.sh: line 8: sudo: command not found
Requirement already satisfied: pymysql in /usr/local/lib/python3.8/dist-packages (1.1.0)
Running /platform/source/s01/v4_engman/m22220000/m22220000_q5_t0.sh
/platform/source/s01/v4_engman/m22220000/m22220000_q5_t0.sh: line 4: sudo: command not found
/platform/source/s01/v4_engman/m22220000/m22220000_q5_t0.sh: line 7: sudo: command not found
Requirement already satisfied: pymysql in /usr/local/lib/python3.8/dist-packages (1.1.0)
Requirement already satisfied: pandas in /usr/local/lib/python3.8/dist-packages (2.0.3)
Requirement already satisfied: python-dateutil>=2.8.2 in /usr/local/lib/python3.8/dist-packages (from pandas) (2.8.2)
Requirement already satisfied: pytz>=2020.1 in /usr/local/lib/python3.8/dist-packages (from pandas) (2023.3.post1)
Requirement already satisfied: tzdata>=2022.1 in /usr/local/lib/python3.8/dist-packages (from pandas) (2023.3)
Requirement already satisfied: numpy>=1.20.3; python_version < "3.10" in /usr/local/lib/python3.8/dist-packages (from pandas) (1.24.4)
Requirement already satisfied: six>=1.5 in /usr/local/lib/python3.8/dist-packages (from python-dateutil>=2.8.2->pandas) (1.16.0)
Running /platform/source/s01/v4_engman/m22220000/m22220000_q6_t0.sh
/platform/source/s01/v4_engman/m22220000/m22220000_q6_t0.sh: line 5: sudo: command not found
/platform/source/s01/v4_engman/m22220000/m22220000_q6_t0.sh: line 6: sudo: command not found
Requirement already satisfied: pymysql in /usr/local/lib/python3.8/dist-packages (1.1.0)
Running /platform/source/s01/v4_engman/m22220000/m22220000_q7_t0.sh
/platform/source/s01/v4_engman/m22220000/m22220000_q7_t0.sh: line 4: sudo: command not found
/platform/source/s01/v4_engman/m22220000/m22220000_q7_t0.sh: line 7: sudo: command not found
Requirement already satisfied: pandas in /usr/local/lib/python3.8/dist-packages (2.0.3)
Requirement already satisfied: pymysql in /usr/local/lib/python3.8/dist-packages (1.1.0)
Requirement already satisfied: redis in /usr/local/lib/python3.8/dist-packages (3.4.1)
Requirement already satisfied: python-dateutil>=2.8.2 in /usr/local/lib/python3.8/dist-packages (from pandas) (2.8.2)
Requirement already satisfied: tzdata>=2022.1 in /usr/local/lib/python3.8/dist-packages (from pandas) (2023.3)
Requirement already satisfied: pytz>=2020.1 in /usr/local/lib/python3.8/dist-packages (from pandas) (2023.3.post1)
Requirement already satisfied: numpy>=1.20.3; python_version < "3.10" in /usr/local/lib/python3.8/dist-packages (from pandas) (1.24.4)
Requirement already satisfied: six>=1.5 in /usr/local/lib/python3.8/dist-packages (from python-dateutil>=2.8.2->pandas) (1.16.0)
/platform/source/s01/v4_engman/m22220000/m22220000_q7_t0.sh: line 13: git: command not found
/platform/source/s01/v4_engman/m22220000/m22220000_q7_t0.sh: line 14: cd: direct_redis: No such file or directory
python3: can't open file 'setup.py': [Errno 2] No such file or directory
python3: can't open file 'run_query.py': [Errno 2] No such file or directory
Running /platform/source/s01/v4_engman/m22220000/m22220000_q8_t0.sh
0% [Working]            Hit:1 http://ports.ubuntu.com/ubuntu-ports focal InRelease
0% [Working]0% [Waiting for headers]                        Hit:2 http://ports.ubuntu.com/ubuntu-ports focal-updates InRelease
                        0% [Working]0% [Waiting for headers]                        Hit:3 http://ports.ubuntu.com/ubuntu-ports focal-backports InRelease
                        0% [Working]0% [Waiting for headers]                        Hit:4 http://ports.ubuntu.com/ubuntu-ports focal-security InRelease
                        0% [Working]20% [Working]             Reading package lists... 0%Reading package lists... 0%Reading package lists... 0%Reading package lists... 6%Reading package lists... 6%Reading package lists... 6%Reading package lists... 6%Reading package lists... 60%Reading package lists... 60%Reading package lists... 61%Reading package lists... 61%Reading package lists... 74%Reading package lists... 74%Reading package lists... 75%Reading package lists... 75%Reading package lists... 81%Reading package lists... 81%Reading package lists... 81%Reading package lists... 81%Reading package lists... 82%Reading package lists... 82%Reading package lists... 82%Reading package lists... 82%Reading package lists... 94%Reading package lists... 94%Reading package lists... 94%Reading package lists... 94%Reading package lists... 99%Reading package lists... 99%Reading package lists... 99%Reading package lists... 99%Reading package lists... Done
Reading package lists... 0%Reading package lists... 0%Reading package lists... 0%Reading package lists... 6%Reading package lists... 6%Reading package lists... 6%Reading package lists... 6%Reading package lists... 60%Reading package lists... 60%Reading package lists... 61%Reading package lists... 61%Reading package lists... 74%Reading package lists... 74%Reading package lists... 75%Reading package lists... 75%Reading package lists... 81%Reading package lists... 81%Reading package lists... 81%Reading package lists... 81%Reading package lists... 82%Reading package lists... 82%Reading package lists... 82%Reading package lists... 82%Reading package lists... 94%Reading package lists... 94%Reading package lists... 94%Reading package lists... 94%Reading package lists... 99%Reading package lists... 99%Reading package lists... 99%Reading package lists... 99%Reading package lists... Done
Building dependency tree... 0%Building dependency tree... 0%Building dependency tree... 50%Building dependency tree... 50%Building dependency tree       
Reading state information... 0%Reading state information... 0%Reading state information... Done
python3-pip is already the newest version (20.0.2-5ubuntu1.10).
0 upgraded, 0 newly installed, 0 to remove and 0 not upgraded.
Requirement already satisfied: pymysql in /usr/local/lib/python3.8/dist-packages (1.1.0)
Requirement already satisfied: pandas in /usr/local/lib/python3.8/dist-packages (2.0.3)
Requirement already satisfied: direct-redis in /usr/local/lib/python3.8/dist-packages (0.3.1)
Requirement already satisfied: numpy>=1.20.3; python_version < "3.10" in /usr/local/lib/python3.8/dist-packages (from pandas) (1.24.4)
Requirement already satisfied: tzdata>=2022.1 in /usr/local/lib/python3.8/dist-packages (from pandas) (2023.3)
Requirement already satisfied: pytz>=2020.1 in /usr/local/lib/python3.8/dist-packages (from pandas) (2023.3.post1)
Requirement already satisfied: python-dateutil>=2.8.2 in /usr/local/lib/python3.8/dist-packages (from pandas) (2.8.2)
Requirement already satisfied: redis==3.4.1 in /usr/local/lib/python3.8/dist-packages (from direct-redis) (3.4.1)
Requirement already satisfied: six>=1.5 in /usr/local/lib/python3.8/dist-packages (from python-dateutil>=2.8.2->pandas) (1.16.0)
Running /platform/source/s01/v4_engman/m22220000/m22220000_q9_t0.sh
0% [Working]            Hit:1 http://ports.ubuntu.com/ubuntu-ports focal InRelease
0% [Working]0% [Waiting for headers]                        Hit:2 http://ports.ubuntu.com/ubuntu-ports focal-updates InRelease
                        0% [Working]0% [Waiting for headers]                        Hit:3 http://ports.ubuntu.com/ubuntu-ports focal-backports InRelease
                        0% [Working]0% [Waiting for headers]                        Hit:4 http://ports.ubuntu.com/ubuntu-ports focal-security InRelease
                        0% [Working]20% [Working]             Reading package lists... 0%Reading package lists... 0%Reading package lists... 0%Reading package lists... 6%Reading package lists... 6%Reading package lists... 6%Reading package lists... 6%Reading package lists... 60%Reading package lists... 60%Reading package lists... 61%Reading package lists... 61%Reading package lists... 74%Reading package lists... 74%Reading package lists... 75%Reading package lists... 75%Reading package lists... 81%Reading package lists... 81%Reading package lists... 81%Reading package lists... 81%Reading package lists... 82%Reading package lists... 82%Reading package lists... 82%Reading package lists... 82%Reading package lists... 94%Reading package lists... 94%Reading package lists... 94%Reading package lists... 94%Reading package lists... 99%Reading package lists... 99%Reading package lists... 99%Reading package lists... 99%Reading package lists... Done
Reading package lists... 0%Reading package lists... 0%Reading package lists... 0%Reading package lists... 6%Reading package lists... 6%Reading package lists... 6%Reading package lists... 6%Reading package lists... 60%Reading package lists... 60%Reading package lists... 61%Reading package lists... 61%Reading package lists... 74%Reading package lists... 74%Reading package lists... 75%Reading package lists... 75%Reading package lists... 81%Reading package lists... 81%Reading package lists... 81%Reading package lists... 81%Reading package lists... 82%Reading package lists... 82%Reading package lists... 82%Reading package lists... 82%Reading package lists... 94%Reading package lists... 94%Reading package lists... 94%Reading package lists... 94%Reading package lists... 99%Reading package lists... 99%Reading package lists... 99%Reading package lists... 99%Reading package lists... Done
Building dependency tree... 0%Building dependency tree... 0%Building dependency tree... 50%Building dependency tree... 50%Building dependency tree       
Reading state information... 0%Reading state information... 0%Reading state information... Done
python3 is already the newest version (3.8.2-0ubuntu2).
python3-pip is already the newest version (20.0.2-5ubuntu1.10).
The following additional packages will be installed:
  libmysqlclient-dev libmysqlclient21 libssl-dev
Suggested packages:
  libssl-doc
The following NEW packages will be installed:
  default-libmysqlclient-dev libmysqlclient-dev libmysqlclient21 libssl-dev
0 upgraded, 4 newly installed, 0 to remove and 0 not upgraded.
Need to get 4321 kB of archives.
After this operation, 25.1 MB of additional disk space will be used.
0% [Working]            Get:1 http://ports.ubuntu.com/ubuntu-ports focal-updates/main arm64 libmysqlclient21 arm64 8.0.35-0ubuntu0.20.04.1 [1256 kB]
0% [1 libmysqlclient21 4089 B/1256 kB 0%]8% [1 libmysqlclient21 405 kB/1256 kB 32%]                                          28% [Working]             Get:2 http://ports.ubuntu.com/ubuntu-ports focal-updates/main arm64 libssl-dev arm64 1.1.1f-1ubuntu2.20 [1460 kB]
28% [2 libssl-dev 11.3 kB/1460 kB 1%]                                     60% [Waiting for headers]                         Get:3 http://ports.ubuntu.com/ubuntu-ports focal-updates/main arm64 libmysqlclient-dev arm64 8.0.35-0ubuntu0.20.04.1 [1601 kB]
61% [3 libmysqlclient-dev 28.0 kB/1601 kB 2%]                                             95% [Waiting for headers]                         Get:4 http://ports.ubuntu.com/ubuntu-ports focal/main arm64 default-libmysqlclient-dev arm64 1.0.5ubuntu2 [3932 B]
                         100% [Working]              Fetched 4321 kB in 1s (3505 kB/s)
debconf: delaying package configuration, since apt-utils is not installed
Selecting previously unselected package libmysqlclient21:arm64.
(Reading database ... (Reading database ... 5%(Reading database ... 10%(Reading database ... 15%(Reading database ... 20%(Reading database ... 25%(Reading database ... 30%(Reading database ... 35%(Reading database ... 40%(Reading database ... 45%(Reading database ... 50%(Reading database ... 55%(Reading database ... 60%(Reading database ... 65%(Reading database ... 70%(Reading database ... 75%(Reading database ... 80%(Reading database ... 85%(Reading database ... 90%(Reading database ... 95%(Reading database ... 100%(Reading database ... 14446 files and directories currently installed.)
Preparing to unpack .../libmysqlclient21_8.0.35-0ubuntu0.20.04.1_arm64.deb ...
Unpacking libmysqlclient21:arm64 (8.0.35-0ubuntu0.20.04.1) ...
Selecting previously unselected package libssl-dev:arm64.
Preparing to unpack .../libssl-dev_1.1.1f-1ubuntu2.20_arm64.deb ...
Unpacking libssl-dev:arm64 (1.1.1f-1ubuntu2.20) ...
Selecting previously unselected package libmysqlclient-dev.
Preparing to unpack .../libmysqlclient-dev_8.0.35-0ubuntu0.20.04.1_arm64.deb ...
Unpacking libmysqlclient-dev (8.0.35-0ubuntu0.20.04.1) ...
Selecting previously unselected package default-libmysqlclient-dev:arm64.
Preparing to unpack .../default-libmysqlclient-dev_1.0.5ubuntu2_arm64.deb ...
Unpacking default-libmysqlclient-dev:arm64 (1.0.5ubuntu2) ...
Setting up libmysqlclient21:arm64 (8.0.35-0ubuntu0.20.04.1) ...
Setting up libssl-dev:arm64 (1.1.1f-1ubuntu2.20) ...
Setting up libmysqlclient-dev (8.0.35-0ubuntu0.20.04.1) ...
Setting up default-libmysqlclient-dev:arm64 (1.0.5ubuntu2) ...
Processing triggers for libc-bin (2.31-0ubuntu9.12) ...
Requirement already satisfied: pymysql in /usr/local/lib/python3.8/dist-packages (1.1.0)
Requirement already satisfied: pandas in /usr/local/lib/python3.8/dist-packages (2.0.3)
Requirement already satisfied: redis in /usr/local/lib/python3.8/dist-packages (3.4.1)
Requirement already satisfied: direct_redis in /usr/local/lib/python3.8/dist-packages (0.3.1)
Requirement already satisfied: tzdata>=2022.1 in /usr/local/lib/python3.8/dist-packages (from pandas) (2023.3)
Requirement already satisfied: pytz>=2020.1 in /usr/local/lib/python3.8/dist-packages (from pandas) (2023.3.post1)
Requirement already satisfied: numpy>=1.20.3; python_version < "3.10" in /usr/local/lib/python3.8/dist-packages (from pandas) (1.24.4)
Requirement already satisfied: python-dateutil>=2.8.2 in /usr/local/lib/python3.8/dist-packages (from pandas) (2.8.2)
Requirement already satisfied: six>=1.5 in /usr/local/lib/python3.8/dist-packages (from python-dateutil>=2.8.2->pandas) (1.16.0)
python /dbknitter/dbknitter/grader.py /platform/source/s01/v4_engman/m22220000/m22220000_q10_t0.py /platform/output/s01/v4_engman/m22220000/m22220000_q10_t0.csv /platform/expected/s01/q10.csv
Traceback (most recent call last):
  File "/platform/source/s01/v4_engman/m22220000/m22220000_q10_t0.py", line 47, in <module>
    nation_df = pd.DataFrame(eval(nation_data), columns=["N_NATIONKEY", "N_NAME", "N_REGIONKEY", "N_COMMENT"])
TypeError: eval() arg 1 must be a string, bytes or code object
Score.fail_execute
python /dbknitter/dbknitter/grader.py /platform/source/s01/v4_engman/m22220000/m22220000_q11_t0.py /platform/output/s01/v4_engman/m22220000/m22220000_q11_t0.csv /platform/expected/s01/q11.csv
/platform/source/s01/v4_engman/m22220000/m22220000_q11_t0.py:13: UserWarning: pandas only supports SQLAlchemy connectable (engine/connection) or database string URI or sqlite3 DBAPI2 connection. Other DBAPI2 objects are not tested. Please consider using SQLAlchemy.
  partsupp_df = pd.read_sql(ps_query, mysql_connection)
Traceback (most recent call last):
  File "/platform/source/s01/v4_engman/m22220000/m22220000_q11_t0.py", line 22, in <module>
    nation_df = pd.read_json(redis_connection.get('nation'), orient='records')
  File "/usr/local/lib/python3.8/dist-packages/pandas/io/json/_json.py", line 760, in read_json
    json_reader = JsonReader(
  File "/usr/local/lib/python3.8/dist-packages/pandas/io/json/_json.py", line 861, in __init__
    data = self._get_data_from_filepath(filepath_or_buffer)
  File "/usr/local/lib/python3.8/dist-packages/pandas/io/json/_json.py", line 901, in _get_data_from_filepath
    self.handles = get_handle(
  File "/usr/local/lib/python3.8/dist-packages/pandas/io/common.py", line 707, in get_handle
    if _is_binary_mode(path_or_buf, mode) and "b" not in mode:
  File "/usr/local/lib/python3.8/dist-packages/pandas/io/common.py", line 1167, in _is_binary_mode
    return isinstance(handle, _get_binary_io_classes()) or "b" in getattr(
TypeError: argument of type 'method' is not iterable
Score.fail_execute
python /dbknitter/dbknitter/grader.py /platform/source/s01/v4_engman/m22220000/m22220000_q12_t0.py /platform/output/s01/v4_engman/m22220000/m22220000_q12_t0.csv /platform/expected/s01/q12.csv
>>> Expected ((2, 3))
   HIGH_LINE_COUNT  LOW_LINE_COUNT L_SHIPMODE
0              647             945       MAIL
1              620             943       SHIP

>>> Actual ((2, 3))
   high_priority_count  low_priority_count ship_mode
0                  651                 946      MAIL
1                  621                 945      SHIP

Head row similarity: 0.6508474576271186
Score.fail_wrong_output
python /dbknitter/dbknitter/grader.py /platform/source/s01/v4_engman/m22220000/m22220000_q13_t0.py /platform/output/s01/v4_engman/m22220000/m22220000_q13_t0.csv /platform/expected/s01/q13.csv
>>> Expected ((37, 2))
    CUSTDIST  C_COUNT
0       5000        0
1        676       10
2        651        9
3        618       11
4        554       12
5        548        8
6        514       13
7        487        7
8        485       19
9        461       18
10       454       14
11       444       20
12       442       16
13       438       17
14       430       15
15       396       21
16       378       22
17       355        6
18       322       23
19       262       24
20       188       25
21       184        5
22       162       26
23       138       27
24       103       28
25        92        4
26        59       29
27        49        3
28        29       30
29        26       31
30        19       32
31        12        2
32         8       33
33         7       34
34         5       35
35         3        1
36         1       36

>>> Actual ((36, 2))
    num_customers  num_orders
0               3           1
1              12           2
2              49           3
3              92           4
4             184           5
5             355           6
6             487           7
7             548           8
8             651           9
9             676          10
10            618          11
11            554          12
12            514          13
13            454          14
14            430          15
15            442          16
16            438          17
17            461          18
18            485          19
19            444          20
20            396          21
21            378          22
22            322          23
23            262          24
24            188          25
25            162          26
26            138          27
27            103          28
28             59          29
29             29          30
30             26          31
31             19          32
32              8          33
33              7          34
34              5          35
35              1          36

Score.fail_wrong_output
python /dbknitter/dbknitter/grader.py /platform/source/s01/v4_engman/m22220000/m22220000_q14_t0.py /platform/output/s01/v4_engman/m22220000/m22220000_q14_t0.csv /platform/expected/s01/q14.csv
/platform/source/s01/v4_engman/m22220000/m22220000_q14_t0.py:20: UserWarning: pandas only supports SQLAlchemy connectable (engine/connection) or database string URI or sqlite3 DBAPI2 connection. Other DBAPI2 objects are not tested. Please consider using SQLAlchemy.
  lineitem_df = pd.read_sql(lineitem_query, mysql_conn)
Traceback (most recent call last):
  File "/platform/source/s01/v4_engman/m22220000/m22220000_q14_t0.py", line 29, in <module>
    part_df = pd.read_json(redis.get('part'), orient='records')
  File "/usr/local/lib/python3.8/dist-packages/pandas/io/json/_json.py", line 760, in read_json
    json_reader = JsonReader(
  File "/usr/local/lib/python3.8/dist-packages/pandas/io/json/_json.py", line 861, in __init__
    data = self._get_data_from_filepath(filepath_or_buffer)
  File "/usr/local/lib/python3.8/dist-packages/pandas/io/json/_json.py", line 901, in _get_data_from_filepath
    self.handles = get_handle(
  File "/usr/local/lib/python3.8/dist-packages/pandas/io/common.py", line 707, in get_handle
    if _is_binary_mode(path_or_buf, mode) and "b" not in mode:
  File "/usr/local/lib/python3.8/dist-packages/pandas/io/common.py", line 1167, in _is_binary_mode
    return isinstance(handle, _get_binary_io_classes()) or "b" in getattr(
TypeError: argument of type 'method' is not iterable
Score.fail_execute
python /dbknitter/dbknitter/grader.py /platform/source/s01/v4_engman/m22220000/m22220000_q15_t0.py /platform/output/s01/v4_engman/m22220000/m22220000_q15_t0.csv /platform/expected/s01/q15.csv
/platform/source/s01/v4_engman/m22220000/m22220000_q15_t0.py:27: UserWarning: pandas only supports SQLAlchemy connectable (engine/connection) or database string URI or sqlite3 DBAPI2 connection. Other DBAPI2 objects are not tested. Please consider using SQLAlchemy.
  lineitem_df = pd.read_sql(sql_query, con=mysql_conn)
Traceback (most recent call last):
  File "/platform/source/s01/v4_engman/m22220000/m22220000_q15_t0.py", line 40, in <module>
    supplier_df = pd.read_msgpack(redis_conn.get('supplier'))
AttributeError: module 'pandas' has no attribute 'read_msgpack'
Score.fail_execute
python /dbknitter/dbknitter/grader.py /platform/source/s01/v4_engman/m22220000/m22220000_q16_t0.py /platform/output/s01/v4_engman/m22220000/m22220000_q16_t0.csv /platform/expected/s01/q16.csv
/platform/source/s01/v4_engman/m22220000/m22220000_q16_t0.py:19: UserWarning: pandas only supports SQLAlchemy connectable (engine/connection) or database string URI or sqlite3 DBAPI2 connection. Other DBAPI2 objects are not tested. Please consider using SQLAlchemy.
  ps_df = pd.read_sql(ps_query, mysql_connection)
Traceback (most recent call last):
  File "/usr/local/lib/python3.8/dist-packages/pandas/io/sql.py", line 2202, in execute
    cur.execute(sql, *args)
  File "/usr/local/lib/python3.8/dist-packages/pymysql/cursors.py", line 153, in execute
    result = self._query(query)
  File "/usr/local/lib/python3.8/dist-packages/pymysql/cursors.py", line 322, in _query
    conn.query(q)
  File "/usr/local/lib/python3.8/dist-packages/pymysql/connections.py", line 558, in query
    self._affected_rows = self._read_query_result(unbuffered=unbuffered)
  File "/usr/local/lib/python3.8/dist-packages/pymysql/connections.py", line 822, in _read_query_result
    result.read()
  File "/usr/local/lib/python3.8/dist-packages/pymysql/connections.py", line 1200, in read
    first_packet = self.connection._read_packet()
  File "/usr/local/lib/python3.8/dist-packages/pymysql/connections.py", line 772, in _read_packet
    packet.raise_for_error()
  File "/usr/local/lib/python3.8/dist-packages/pymysql/protocol.py", line 221, in raise_for_error
    err.raise_mysql_exception(self._data)
  File "/usr/local/lib/python3.8/dist-packages/pymysql/err.py", line 143, in raise_mysql_exception
    raise errorclass(errno, errval)
pymysql.err.ProgrammingError: (1146, "Table 'tpch.supplier' doesn't exist")

The above exception was the direct cause of the following exception:

Traceback (most recent call last):
  File "/platform/source/s01/v4_engman/m22220000/m22220000_q16_t0.py", line 19, in <module>
    ps_df = pd.read_sql(ps_query, mysql_connection)
  File "/usr/local/lib/python3.8/dist-packages/pandas/io/sql.py", line 635, in read_sql
    return pandas_sql.read_query(
  File "/usr/local/lib/python3.8/dist-packages/pandas/io/sql.py", line 2266, in read_query
    cursor = self.execute(sql, params)
  File "/usr/local/lib/python3.8/dist-packages/pandas/io/sql.py", line 2214, in execute
    raise ex from exc
pandas.errors.DatabaseError: Execution failed on sql 'SELECT PS_PARTKEY, PS_SUPPKEY FROM partsupp WHERE PS_PARTKEY NOT IN (
                SELECT PS_PARTKEY FROM partsupp 
                JOIN supplier ON PS_SUPPKEY = S_SUPPKEY
                WHERE S_COMMENT LIKE '%%complaints%%'
              )': (1146, "Table 'tpch.supplier' doesn't exist")
Score.fail_execute
python /dbknitter/dbknitter/grader.py /platform/source/s01/v4_engman/m22220000/m22220000_q17_t0.py /platform/output/s01/v4_engman/m22220000/m22220000_q17_t0.csv /platform/expected/s01/q17.csv
/platform/source/s01/v4_engman/m22220000/m22220000_q17_t0.py:23: UserWarning: pandas only supports SQLAlchemy connectable (engine/connection) or database string URI or sqlite3 DBAPI2 connection. Other DBAPI2 objects are not tested. Please consider using SQLAlchemy.
  lineitem_df = pd.read_sql(lineitem_query, mysql_conn)
Traceback (most recent call last):
  File "/platform/source/s01/v4_engman/m22220000/m22220000_q17_t0.py", line 29, in <module>
    part_df = pd.read_msgpack(redis_conn.get('part'))
AttributeError: module 'pandas' has no attribute 'read_msgpack'
Score.fail_execute
python /dbknitter/dbknitter/grader.py /platform/source/s01/v4_engman/m22220000/m22220000_q18_t0.py /platform/output/s01/v4_engman/m22220000/m22220000_q18_t0.csv /platform/expected/s01/q18.csv
>>> Expected ((5, 6))
   C_CUSTKEY              C_NAME O_ORDERDATE  O_ORDERKEY  O_TOTALPRICE  SUM(L_QUANTITY)
0       1639  Customer#000001639  1994-04-12      502886     456423.88              312
1       6655  Customer#000006655  1995-10-21       29158     452805.02              305
2      14110  Customer#000014110  1995-09-24      565574     425099.85              301
3       1775  Customer#000001775  1997-04-09        6882     408368.10              303
4      11459  Customer#000011459  1993-05-19      551136     386812.74              308

>>> Actual ((5, 6))
   C_CUSTKEY              C_NAME O_ORDERDATE  O_ORDERKEY  O_TOTALPRICE  total_quantity
0       1639  Customer#000001639  1994-04-12      502886     456423.88           312.0
1       6655  Customer#000006655  1995-10-21       29158     452805.02           305.0
2      14110  Customer#000014110  1995-09-24      565574     425099.85           301.0
3       1775  Customer#000001775  1997-04-09        6882     408368.10           303.0
4      11459  Customer#000011459  1993-05-19      551136     386812.74           308.0

Head row similarity: 0.9217557251908397
Score.success_approx
python /dbknitter/dbknitter/grader.py /platform/source/s01/v4_engman/m22220000/m22220000_q19_t0.py /platform/output/s01/v4_engman/m22220000/m22220000_q19_t0.csv /platform/expected/s01/q19.csv
Traceback (most recent call last):
  File "/platform/source/s01/v4_engman/m22220000/m22220000_q19_t0.py", line 21, in <module>
    part_df = pd.read_json(part_data)
  File "/usr/local/lib/python3.8/dist-packages/pandas/io/json/_json.py", line 760, in read_json
    json_reader = JsonReader(
  File "/usr/local/lib/python3.8/dist-packages/pandas/io/json/_json.py", line 861, in __init__
    data = self._get_data_from_filepath(filepath_or_buffer)
  File "/usr/local/lib/python3.8/dist-packages/pandas/io/json/_json.py", line 901, in _get_data_from_filepath
    self.handles = get_handle(
  File "/usr/local/lib/python3.8/dist-packages/pandas/io/common.py", line 707, in get_handle
    if _is_binary_mode(path_or_buf, mode) and "b" not in mode:
  File "/usr/local/lib/python3.8/dist-packages/pandas/io/common.py", line 1167, in _is_binary_mode
    return isinstance(handle, _get_binary_io_classes()) or "b" in getattr(
TypeError: argument of type 'method' is not iterable
Score.fail_execute
python /dbknitter/dbknitter/grader.py /platform/source/s01/v4_engman/m22220000/m22220000_q1_t0.py /platform/output/s01/v4_engman/m22220000/m22220000_q1_t0.csv /platform/expected/s01/q1.csv
>>> Expected ((4, 10))
   AVG_DISC     AVG_PRICE    AVG_QTY  COUNT_ORDER L_LINESTATUS L_RETURNFLAG  SUM_BASE_PRICE    SUM_CHARGE  SUM_DISC_PRICE  SUM_QTY
0  0.050145  36002.123829  25.537587       147790            F            A    5.320754e+09  5.256751e+09    5.054096e+09  3774200
1  0.049394  35521.326916  25.300664         3765            F            N    1.337378e+08  1.322863e+08    1.271324e+08    95257
2  0.050096  36000.924688  25.545538       292000            O            N    1.051227e+10  1.038558e+10    9.986238e+09  7459297
3  0.049989  35994.029214  25.525944       148301            F            R    5.337951e+09  5.274406e+09    5.071819e+09  3785523

>>> Actual ((4, 10))
   AVG_DISC     AVG_PRICE    AVG_QTY  COUNT_ORDER L_LINESTATUS L_RETURNFLAG  SUM_BASE_PRICE    SUM_CHARGE  SUM_DISC_PRICE    SUM_QTY
0  0.050145  36002.123829  25.537587       147790            F            A    5.320754e+09  5.256751e+09    5.054096e+09  3774200.0
1  0.049394  35521.326916  25.300664         3765            F            N    1.337378e+08  1.322863e+08    1.271324e+08    95257.0
2  0.050097  36000.382356  25.545184       291817            O            N    1.050552e+10  1.037890e+10    9.979831e+09  7454519.0
3  0.049989  35994.029214  25.525944       148301            F            R    5.337951e+09  5.274406e+09    5.071819e+09  3785523.0

Head row similarity: 0.8619119878603946
Score.success_approx
python /dbknitter/dbknitter/grader.py /platform/source/s01/v4_engman/m22220000/m22220000_q20_t0.py /platform/output/s01/v4_engman/m22220000/m22220000_q20_t0.csv /platform/expected/s01/q20.csv
Traceback (most recent call last):
  File "/platform/source/s01/v4_engman/m22220000/m22220000_q20_t0.py", line 15, in <module>
    part_data = eval(redis_conn.get('part'))
TypeError: eval() arg 1 must be a string, bytes or code object
Score.fail_execute
python /dbknitter/dbknitter/grader.py /platform/source/s01/v4_engman/m22220000/m22220000_q21_t0.py /platform/output/s01/v4_engman/m22220000/m22220000_q21_t0.csv /platform/expected/s01/q21.csv
Traceback (most recent call last):
  File "/platform/source/s01/v4_engman/m22220000/m22220000_q21_t0.py", line 40, in <module>
    nation = pd.read_json(redis_client.get('nation'), orient='records')
  File "/usr/local/lib/python3.8/dist-packages/pandas/io/json/_json.py", line 760, in read_json
    json_reader = JsonReader(
  File "/usr/local/lib/python3.8/dist-packages/pandas/io/json/_json.py", line 861, in __init__
    data = self._get_data_from_filepath(filepath_or_buffer)
  File "/usr/local/lib/python3.8/dist-packages/pandas/io/json/_json.py", line 901, in _get_data_from_filepath
    self.handles = get_handle(
  File "/usr/local/lib/python3.8/dist-packages/pandas/io/common.py", line 707, in get_handle
    if _is_binary_mode(path_or_buf, mode) and "b" not in mode:
  File "/usr/local/lib/python3.8/dist-packages/pandas/io/common.py", line 1167, in _is_binary_mode
    return isinstance(handle, _get_binary_io_classes()) or "b" in getattr(
TypeError: argument of type 'method' is not iterable
Score.fail_execute
python /dbknitter/dbknitter/grader.py /platform/source/s01/v4_engman/m22220000/m22220000_q22_t0.py /platform/output/s01/v4_engman/m22220000/m22220000_q22_t0.csv /platform/expected/s01/q22.csv
>>> Expected ((4, 3))
   CNTRYCODE  NUMCUST  TOTACCTBAL
0         20       91   666158.10
1         21      101   760953.55
2         22      106   759804.81
3         30       87   646748.02

>>> Actual ((4, 3))
   CNTRYCODE  num_customers  total_acct_balance
0         20            288          2128500.88
1         21            273          2079060.76
2         22            295          2185193.37
3         30            249          1879317.96

Head row similarity: 0.5686274509803921
Score.fail_wrong_output
python /dbknitter/dbknitter/grader.py /platform/source/s01/v4_engman/m22220000/m22220000_q2_t0.py /platform/output/s01/v4_engman/m22220000/m22220000_q2_t0.csv /platform/expected/s01/q2.csv
/platform/source/s01/v4_engman/m22220000/m22220000_q2_t0.py:12: UserWarning: pandas only supports SQLAlchemy connectable (engine/connection) or database string URI or sqlite3 DBAPI2 connection. Other DBAPI2 objects are not tested. Please consider using SQLAlchemy.
  partsupp_df = pd.read_sql(query, conn)
Traceback (most recent call last):
  File "/platform/source/s01/v4_engman/m22220000/m22220000_q2_t0.py", line 59, in <module>
    region_df, nation_df, part_df, supplier_df = get_redis_data()
  File "/platform/source/s01/v4_engman/m22220000/m22220000_q2_t0.py", line 18, in get_redis_data
    region_df = pd.DataFrame(json.loads(redis_client.get('region')))
  File "/usr/lib/python3.8/json/__init__.py", line 341, in loads
    raise TypeError(f'the JSON object must be str, bytes or bytearray, '
TypeError: the JSON object must be str, bytes or bytearray, not DataFrame
Score.fail_execute
python /dbknitter/dbknitter/grader.py /platform/source/s01/v4_engman/m22220000/m22220000_q3_t0.py /platform/output/s01/v4_engman/m22220000/m22220000_q3_t0.csv /platform/expected/s01/q3.csv
>>> Expected ((1216, 4))
      L_ORDERKEY O_ORDERDATE  O_SHIPPRIORITY      REVENUE
0         223140  1995-03-14               0  355369.0698
1         584291  1995-02-21               0  354494.7318
2         405063  1995-03-03               0  353125.4577
3         573861  1995-03-09               0  351238.2770
4         554757  1995-03-14               0  349181.7426
...          ...         ...             ...          ...
1211      152096  1995-01-25               0    1113.2000
1212      521728  1994-12-14               0    1013.7761
1213      445159  1994-12-06               0     949.6260
1214      598597  1994-12-03               0     939.0182
1215      135490  1994-12-20               0     934.9592

[1216 rows x 4 columns]

>>> Actual ((1097, 4))
     O_ORDERDATE  O_ORDERKEY  O_SHIPPRIORITY      REVENUE
0     1995-02-21      584291               0  354494.7318
1     1995-03-03      405063               0  353125.4577
2     1995-02-20      108514               0  314967.0754
3     1995-02-25      178727               0  309728.9306
4     1995-02-21      143905               0  309101.4094
...          ...         ...             ...          ...
1092  1995-01-25      152096               0    1113.2000
1093  1994-12-14      521728               0    1013.7761
1094  1994-12-06      445159               0     949.6260
1095  1994-12-03      598597               0     939.0182
1096  1994-12-20      135490               0     934.9592

[1097 rows x 4 columns]

Score.fail_wrong_output
python /dbknitter/dbknitter/grader.py /platform/source/s01/v4_engman/m22220000/m22220000_q4_t0.py /platform/output/s01/v4_engman/m22220000/m22220000_q4_t0.csv /platform/expected/s01/q4.csv
>>> Expected ((5, 2))
   ORDER_COUNT  O_ORDERPRIORITY
0          999         1-URGENT
1          997           2-HIGH
2         1031         3-MEDIUM
3          989  4-NOT SPECIFIED
4         1077            5-LOW

>>> Actual ((5, 2))
   ORDER_COUNT  O_ORDERPRIORITY
0          999         1-URGENT
1          997           2-HIGH
2         1031         3-MEDIUM
3          989  4-NOT SPECIFIED
4         1077            5-LOW

Score.success
python /dbknitter/dbknitter/grader.py /platform/source/s01/v4_engman/m22220000/m22220000_q5_t0.py /platform/output/s01/v4_engman/m22220000/m22220000_q5_t0.csv /platform/expected/s01/q5.csv
/platform/source/s01/v4_engman/m22220000/m22220000_q5_t0.py:16: UserWarning: pandas only supports SQLAlchemy connectable (engine/connection) or database string URI or sqlite3 DBAPI2 connection. Other DBAPI2 objects are not tested. Please consider using SQLAlchemy.
  mysql_df = pd.read_sql(mysql_query, mysql_conn)
Traceback (most recent call last):
  File "/usr/local/lib/python3.8/dist-packages/pandas/core/indexes/base.py", line 3653, in get_loc
    return self._engine.get_loc(casted_key)
  File "pandas/_libs/index.pyx", line 147, in pandas._libs.index.IndexEngine.get_loc
  File "pandas/_libs/index.pyx", line 176, in pandas._libs.index.IndexEngine.get_loc
  File "pandas/_libs/hashtable_class_helper.pxi", line 7080, in pandas._libs.hashtable.PyObjectHashTable.get_item
  File "pandas/_libs/hashtable_class_helper.pxi", line 7088, in pandas._libs.hashtable.PyObjectHashTable.get_item
KeyError: 'C_NATIONKEY'

The above exception was the direct cause of the following exception:

Traceback (most recent call last):
  File "/platform/source/s01/v4_engman/m22220000/m22220000_q5_t0.py", line 30, in <module>
    asia_customers = mysql_df[mysql_df['C_NATIONKEY'].isin(asia_nations['N_NATIONKEY'])]
  File "/usr/local/lib/python3.8/dist-packages/pandas/core/frame.py", line 3761, in __getitem__
    indexer = self.columns.get_loc(key)
  File "/usr/local/lib/python3.8/dist-packages/pandas/core/indexes/base.py", line 3655, in get_loc
    raise KeyError(key) from err
KeyError: 'C_NATIONKEY'
Score.fail_execute
python /dbknitter/dbknitter/grader.py /platform/source/s01/v4_engman/m22220000/m22220000_q6_t0.py /platform/output/s01/v4_engman/m22220000/m22220000_q6_t0.csv /platform/expected/s01/q6.csv
>>> Expected ((1, 1))
        REVENUE
0  7.115407e+06

>>> Actual ((1, 1))
        REVENUE
0  1.178283e+07

Head row similarity: 0.8064516129032258
Score.success_approx
python /dbknitter/dbknitter/grader.py /platform/source/s01/v4_engman/m22220000/m22220000_q7_t0.py /platform/output/s01/v4_engman/m22220000/m22220000_q7_t0.csv /platform/expected/s01/q7.csv
/platform/source/s01/v4_engman/m22220000/m22220000_q7_t0.py:43: UserWarning: pandas only supports SQLAlchemy connectable (engine/connection) or database string URI or sqlite3 DBAPI2 connection. Other DBAPI2 objects are not tested. Please consider using SQLAlchemy.
  mysql_df = pd.read_sql(mysql_query, mysql_conn)
Traceback (most recent call last):
  File "/usr/local/lib/python3.8/dist-packages/pandas/io/sql.py", line 2202, in execute
    cur.execute(sql, *args)
  File "/usr/local/lib/python3.8/dist-packages/pymysql/cursors.py", line 153, in execute
    result = self._query(query)
  File "/usr/local/lib/python3.8/dist-packages/pymysql/cursors.py", line 322, in _query
    conn.query(q)
  File "/usr/local/lib/python3.8/dist-packages/pymysql/connections.py", line 558, in query
    self._affected_rows = self._read_query_result(unbuffered=unbuffered)
  File "/usr/local/lib/python3.8/dist-packages/pymysql/connections.py", line 822, in _read_query_result
    result.read()
  File "/usr/local/lib/python3.8/dist-packages/pymysql/connections.py", line 1200, in read
    first_packet = self.connection._read_packet()
  File "/usr/local/lib/python3.8/dist-packages/pymysql/connections.py", line 772, in _read_packet
    packet.raise_for_error()
  File "/usr/local/lib/python3.8/dist-packages/pymysql/protocol.py", line 221, in raise_for_error
    err.raise_mysql_exception(self._data)
  File "/usr/local/lib/python3.8/dist-packages/pymysql/err.py", line 143, in raise_mysql_exception
    raise errorclass(errno, errval)
pymysql.err.OperationalError: (1054, "Unknown column 's.N_NAME' in 'field list'")

The above exception was the direct cause of the following exception:

Traceback (most recent call last):
  File "/platform/source/s01/v4_engman/m22220000/m22220000_q7_t0.py", line 43, in <module>
    mysql_df = pd.read_sql(mysql_query, mysql_conn)
  File "/usr/local/lib/python3.8/dist-packages/pandas/io/sql.py", line 635, in read_sql
    return pandas_sql.read_query(
  File "/usr/local/lib/python3.8/dist-packages/pandas/io/sql.py", line 2266, in read_query
    cursor = self.execute(sql, params)
  File "/usr/local/lib/python3.8/dist-packages/pandas/io/sql.py", line 2214, in execute
    raise ex from exc
pandas.errors.DatabaseError: Execution failed on sql '
SELECT 
    c.C_NAME AS CUST_NATION, 
    YEAR(o.O_ORDERDATE) AS L_YEAR, 
    SUM(l.L_EXTENDEDPRICE * (1 - l.L_DISCOUNT)) AS REVENUE,
    s.N_NAME AS SUPP_NATION
FROM
    customer c
JOIN
    orders o ON c.C_CUSTKEY = o.O_CUSTKEY
JOIN
    lineitem l ON o.O_ORDERKEY = l.L_ORDERKEY
WHERE
    c.C_NATIONKEY IN ('INDIA', 'JAPAN')
AND
    s.S_NATIONKEY IN ('INDIA', 'JAPAN')
AND 
    c.C_NATIONKEY <> s.S_NATIONKEY
AND 
    YEAR(o.O_ORDERDATE) IN (1995, 1996)
AND 
    l.L_SHIPDATE BETWEEN o.O_ORDERDATE AND DATE_ADD(o.O_ORDERDATE, INTERVAL 2 YEAR)
GROUP BY
    CUST_NATION, L_YEAR, SUPP_NATION
ORDER BY
    SUPP_NATION, CUST_NATION, L_YEAR
': (1054, "Unknown column 's.N_NAME' in 'field list'")
Score.fail_execute
python /dbknitter/dbknitter/grader.py /platform/source/s01/v4_engman/m22220000/m22220000_q8_t0.py /platform/output/s01/v4_engman/m22220000/m22220000_q8_t0.csv /platform/expected/s01/q8.csv
/platform/source/s01/v4_engman/m22220000/m22220000_q8_t0.py:28: UserWarning: pandas only supports SQLAlchemy connectable (engine/connection) or database string URI or sqlite3 DBAPI2 connection. Other DBAPI2 objects are not tested. Please consider using SQLAlchemy.
  mysql_df = pd.read_sql(mysql_query, mysql_conn)
Traceback (most recent call last):
  File "/platform/source/s01/v4_engman/m22220000/m22220000_q8_t0.py", line 37, in <module>
    nation_df = pd.read_json(redis_client.get('nation'))
  File "/usr/local/lib/python3.8/dist-packages/pandas/io/json/_json.py", line 760, in read_json
    json_reader = JsonReader(
  File "/usr/local/lib/python3.8/dist-packages/pandas/io/json/_json.py", line 861, in __init__
    data = self._get_data_from_filepath(filepath_or_buffer)
  File "/usr/local/lib/python3.8/dist-packages/pandas/io/json/_json.py", line 901, in _get_data_from_filepath
    self.handles = get_handle(
  File "/usr/local/lib/python3.8/dist-packages/pandas/io/common.py", line 707, in get_handle
    if _is_binary_mode(path_or_buf, mode) and "b" not in mode:
  File "/usr/local/lib/python3.8/dist-packages/pandas/io/common.py", line 1167, in _is_binary_mode
    return isinstance(handle, _get_binary_io_classes()) or "b" in getattr(
TypeError: argument of type 'method' is not iterable
Score.fail_execute
python /dbknitter/dbknitter/grader.py /platform/source/s01/v4_engman/m22220000/m22220000_q9_t0.py /platform/output/s01/v4_engman/m22220000/m22220000_q9_t0.csv /platform/expected/s01/q9.csv
/platform/source/s01/v4_engman/m22220000/m22220000_q9_t0.py:22: UserWarning: pandas only supports SQLAlchemy connectable (engine/connection) or database string URI or sqlite3 DBAPI2 connection. Other DBAPI2 objects are not tested. Please consider using SQLAlchemy.
  partsupp_df = pd.read_sql(partsupp_query, mysql_conn)
/platform/source/s01/v4_engman/m22220000/m22220000_q9_t0.py:23: UserWarning: pandas only supports SQLAlchemy connectable (engine/connection) or database string URI or sqlite3 DBAPI2 connection. Other DBAPI2 objects are not tested. Please consider using SQLAlchemy.
  orders_df = pd.read_sql(orders_query, mysql_conn)
/platform/source/s01/v4_engman/m22220000/m22220000_q9_t0.py:24: UserWarning: pandas only supports SQLAlchemy connectable (engine/connection) or database string URI or sqlite3 DBAPI2 connection. Other DBAPI2 objects are not tested. Please consider using SQLAlchemy.
  lineitem_df = pd.read_sql(lineitem_query, mysql_conn)
Traceback (most recent call last):
  File "/usr/local/lib/python3.8/dist-packages/pandas/io/sql.py", line 2202, in execute
    cur.execute(sql, *args)
  File "/usr/local/lib/python3.8/dist-packages/pymysql/cursors.py", line 153, in execute
    result = self._query(query)
  File "/usr/local/lib/python3.8/dist-packages/pymysql/cursors.py", line 322, in _query
    conn.query(q)
  File "/usr/local/lib/python3.8/dist-packages/pymysql/connections.py", line 558, in query
    self._affected_rows = self._read_query_result(unbuffered=unbuffered)
  File "/usr/local/lib/python3.8/dist-packages/pymysql/connections.py", line 822, in _read_query_result
    result.read()
  File "/usr/local/lib/python3.8/dist-packages/pymysql/connections.py", line 1200, in read
    first_packet = self.connection._read_packet()
  File "/usr/local/lib/python3.8/dist-packages/pymysql/connections.py", line 772, in _read_packet
    packet.raise_for_error()
  File "/usr/local/lib/python3.8/dist-packages/pymysql/protocol.py", line 221, in raise_for_error
    err.raise_mysql_exception(self._data)
  File "/usr/local/lib/python3.8/dist-packages/pymysql/err.py", line 143, in raise_mysql_exception
    raise errorclass(errno, errval)
pymysql.err.OperationalError: (1054, "Unknown column 'O_ORDERDATE' in 'where clause'")

The above exception was the direct cause of the following exception:

Traceback (most recent call last):
  File "/platform/source/s01/v4_engman/m22220000/m22220000_q9_t0.py", line 24, in <module>
    lineitem_df = pd.read_sql(lineitem_query, mysql_conn)
  File "/usr/local/lib/python3.8/dist-packages/pandas/io/sql.py", line 635, in read_sql
    return pandas_sql.read_query(
  File "/usr/local/lib/python3.8/dist-packages/pandas/io/sql.py", line 2266, in read_query
    cursor = self.execute(sql, params)
  File "/usr/local/lib/python3.8/dist-packages/pandas/io/sql.py", line 2214, in execute
    raise ex from exc
pandas.errors.DatabaseError: Execution failed on sql '
SELECT L_ORDERKEY, L_PARTKEY, L_SUPPKEY, L_QUANTITY, L_EXTENDEDPRICE, L_DISCOUNT
FROM lineitem
WHERE L_SHIPDATE BETWEEN O_ORDERDATE AND DATE_ADD(O_ORDERDATE, INTERVAL 1 YEAR);
': (1054, "Unknown column 'O_ORDERDATE' in 'where clause'")
Score.fail_execute
