Using MAPPING_STR=21212121, VERSION_DIR=v4_engoff
Running /platform/source/s01/v4_engoff/m21212121/m21212121_q10_t0.sh
Requirement already satisfied: pymongo in /usr/local/lib/python3.8/dist-packages (4.6.0)
Requirement already satisfied: pandas in /usr/local/lib/python3.8/dist-packages (2.0.3)
Requirement already satisfied: direct-redis in /usr/local/lib/python3.8/dist-packages (0.3.1)
Requirement already satisfied: dnspython<3.0.0,>=1.16.0 in /usr/local/lib/python3.8/dist-packages (from pymongo) (2.4.2)
Requirement already satisfied: numpy>=1.20.3; python_version < "3.10" in /usr/local/lib/python3.8/dist-packages (from pandas) (1.24.4)
Requirement already satisfied: pytz>=2020.1 in /usr/local/lib/python3.8/dist-packages (from pandas) (2023.3.post1)
Requirement already satisfied: tzdata>=2022.1 in /usr/local/lib/python3.8/dist-packages (from pandas) (2023.3)
Requirement already satisfied: python-dateutil>=2.8.2 in /usr/local/lib/python3.8/dist-packages (from pandas) (2.8.2)
Requirement already satisfied: redis==3.4.1 in /usr/local/lib/python3.8/dist-packages (from direct-redis) (3.4.1)
Requirement already satisfied: six>=1.5 in /usr/local/lib/python3.8/dist-packages (from python-dateutil>=2.8.2->pandas) (1.16.0)
python: can't open file 'query_code.py': [Errno 2] No such file or directory
Running /platform/source/s01/v4_engoff/m21212121/m21212121_q11_t0.sh
Requirement already satisfied: pymongo in /usr/local/lib/python3.8/dist-packages (4.6.0)
Requirement already satisfied: pandas in /usr/local/lib/python3.8/dist-packages (2.0.3)
Requirement already satisfied: redis in /usr/local/lib/python3.8/dist-packages (3.4.1)
Requirement already satisfied: dnspython<3.0.0,>=1.16.0 in /usr/local/lib/python3.8/dist-packages (from pymongo) (2.4.2)
Requirement already satisfied: tzdata>=2022.1 in /usr/local/lib/python3.8/dist-packages (from pandas) (2023.3)
Requirement already satisfied: numpy>=1.20.3; python_version < "3.10" in /usr/local/lib/python3.8/dist-packages (from pandas) (1.24.4)
Requirement already satisfied: pytz>=2020.1 in /usr/local/lib/python3.8/dist-packages (from pandas) (2023.3.post1)
Requirement already satisfied: python-dateutil>=2.8.2 in /usr/local/lib/python3.8/dist-packages (from pandas) (2.8.2)
Requirement already satisfied: six>=1.5 in /usr/local/lib/python3.8/dist-packages (from python-dateutil>=2.8.2->pandas) (1.16.0)
Running /platform/source/s01/v4_engoff/m21212121/m21212121_q12_t0.sh
Running /platform/source/s01/v4_engoff/m21212121/m21212121_q13_t0.sh
/platform/source/s01/v4_engoff/m21212121/m21212121_q13_t0.sh: line 4: sudo: command not found
/platform/source/s01/v4_engoff/m21212121/m21212121_q13_t0.sh: line 7: sudo: command not found
Requirement already satisfied: pymongo in /usr/local/lib/python3.8/dist-packages (4.6.0)
Requirement already satisfied: dnspython<3.0.0,>=1.16.0 in /usr/local/lib/python3.8/dist-packages (from pymongo) (2.4.2)
Requirement already satisfied: pandas in /usr/local/lib/python3.8/dist-packages (2.0.3)
Requirement already satisfied: python-dateutil>=2.8.2 in /usr/local/lib/python3.8/dist-packages (from pandas) (2.8.2)
Requirement already satisfied: tzdata>=2022.1 in /usr/local/lib/python3.8/dist-packages (from pandas) (2023.3)
Requirement already satisfied: numpy>=1.20.3; python_version < "3.10" in /usr/local/lib/python3.8/dist-packages (from pandas) (1.24.4)
Requirement already satisfied: pytz>=2020.1 in /usr/local/lib/python3.8/dist-packages (from pandas) (2023.3.post1)
Requirement already satisfied: six>=1.5 in /usr/local/lib/python3.8/dist-packages (from python-dateutil>=2.8.2->pandas) (1.16.0)
Running /platform/source/s01/v4_engoff/m21212121/m21212121_q14_t0.sh
Requirement already satisfied: pymongo in /usr/local/lib/python3.8/dist-packages (4.6.0)
Requirement already satisfied: pandas in /usr/local/lib/python3.8/dist-packages (2.0.3)
Requirement already satisfied: direct_redis in /usr/local/lib/python3.8/dist-packages (0.3.1)
Requirement already satisfied: dnspython<3.0.0,>=1.16.0 in /usr/local/lib/python3.8/dist-packages (from pymongo) (2.4.2)
Requirement already satisfied: pytz>=2020.1 in /usr/local/lib/python3.8/dist-packages (from pandas) (2023.3.post1)
Requirement already satisfied: tzdata>=2022.1 in /usr/local/lib/python3.8/dist-packages (from pandas) (2023.3)
Requirement already satisfied: python-dateutil>=2.8.2 in /usr/local/lib/python3.8/dist-packages (from pandas) (2.8.2)
Requirement already satisfied: numpy>=1.20.3; python_version < "3.10" in /usr/local/lib/python3.8/dist-packages (from pandas) (1.24.4)
Requirement already satisfied: redis==3.4.1 in /usr/local/lib/python3.8/dist-packages (from direct_redis) (3.4.1)
Requirement already satisfied: six>=1.5 in /usr/local/lib/python3.8/dist-packages (from python-dateutil>=2.8.2->pandas) (1.16.0)
Running /platform/source/s01/v4_engoff/m21212121/m21212121_q15_t0.sh
/platform/source/s01/v4_engoff/m21212121/m21212121_q15_t0.sh: line 6: sudo: command not found
/platform/source/s01/v4_engoff/m21212121/m21212121_q15_t0.sh: line 9: sudo: command not found
Requirement already satisfied: pymongo in /usr/local/lib/python3.8/dist-packages (4.6.0)
Requirement already satisfied: dnspython<3.0.0,>=1.16.0 in /usr/local/lib/python3.8/dist-packages (from pymongo) (2.4.2)
Running /platform/source/s01/v4_engoff/m21212121/m21212121_q16_t0.sh
/platform/source/s01/v4_engoff/m21212121/m21212121_q16_t0.sh: line 4: sudo: command not found
/platform/source/s01/v4_engoff/m21212121/m21212121_q16_t0.sh: line 7: sudo: command not found
Requirement already satisfied: pymongo in /usr/local/lib/python3.8/dist-packages (4.6.0)
Requirement already satisfied: pandas in /usr/local/lib/python3.8/dist-packages (2.0.3)
Requirement already satisfied: redis in /usr/local/lib/python3.8/dist-packages (3.4.1)
Requirement already satisfied: direct-redis in /usr/local/lib/python3.8/dist-packages (0.3.1)
Requirement already satisfied: dnspython<3.0.0,>=1.16.0 in /usr/local/lib/python3.8/dist-packages (from pymongo) (2.4.2)
Requirement already satisfied: pytz>=2020.1 in /usr/local/lib/python3.8/dist-packages (from pandas) (2023.3.post1)
Requirement already satisfied: tzdata>=2022.1 in /usr/local/lib/python3.8/dist-packages (from pandas) (2023.3)
Requirement already satisfied: numpy>=1.20.3; python_version < "3.10" in /usr/local/lib/python3.8/dist-packages (from pandas) (1.24.4)
Requirement already satisfied: python-dateutil>=2.8.2 in /usr/local/lib/python3.8/dist-packages (from pandas) (2.8.2)
Requirement already satisfied: six>=1.5 in /usr/local/lib/python3.8/dist-packages (from python-dateutil>=2.8.2->pandas) (1.16.0)
Running /platform/source/s01/v4_engoff/m21212121/m21212121_q17_t0.sh
Running /platform/source/s01/v4_engoff/m21212121/m21212121_q18_t0.sh
Running /platform/source/s01/v4_engoff/m21212121/m21212121_q19_t0.sh
/platform/source/s01/v4_engoff/m21212121/m21212121_q19_t0.sh: line 4: sudo: command not found
/platform/source/s01/v4_engoff/m21212121/m21212121_q19_t0.sh: line 5: sudo: command not found
Requirement already satisfied: pymongo in /usr/local/lib/python3.8/dist-packages (4.6.0)
Requirement already satisfied: pandas in /usr/local/lib/python3.8/dist-packages (2.0.3)
Requirement already satisfied: direct-redis in /usr/local/lib/python3.8/dist-packages (0.3.1)
Requirement already satisfied: dnspython<3.0.0,>=1.16.0 in /usr/local/lib/python3.8/dist-packages (from pymongo) (2.4.2)
Requirement already satisfied: python-dateutil>=2.8.2 in /usr/local/lib/python3.8/dist-packages (from pandas) (2.8.2)
Requirement already satisfied: numpy>=1.20.3; python_version < "3.10" in /usr/local/lib/python3.8/dist-packages (from pandas) (1.24.4)
Requirement already satisfied: pytz>=2020.1 in /usr/local/lib/python3.8/dist-packages (from pandas) (2023.3.post1)
Requirement already satisfied: tzdata>=2022.1 in /usr/local/lib/python3.8/dist-packages (from pandas) (2023.3)
Requirement already satisfied: redis==3.4.1 in /usr/local/lib/python3.8/dist-packages (from direct-redis) (3.4.1)
Requirement already satisfied: six>=1.5 in /usr/local/lib/python3.8/dist-packages (from python-dateutil>=2.8.2->pandas) (1.16.0)
Running /platform/source/s01/v4_engoff/m21212121/m21212121_q1_t0.sh
Requirement already satisfied: pymongo in /usr/local/lib/python3.8/dist-packages (4.6.0)
Requirement already satisfied: dnspython<3.0.0,>=1.16.0 in /usr/local/lib/python3.8/dist-packages (from pymongo) (2.4.2)
Running /platform/source/s01/v4_engoff/m21212121/m21212121_q20_t0.sh
/platform/source/s01/v4_engoff/m21212121/m21212121_q20_t0.sh: line 3: sudo: command not found
/platform/source/s01/v4_engoff/m21212121/m21212121_q20_t0.sh: line 6: sudo: command not found
Requirement already satisfied: pymongo in /usr/local/lib/python3.8/dist-packages (4.6.0)
Requirement already satisfied: redis in /usr/local/lib/python3.8/dist-packages (3.4.1)
Requirement already satisfied: pandas in /usr/local/lib/python3.8/dist-packages (2.0.3)
Requirement already satisfied: direct_redis in /usr/local/lib/python3.8/dist-packages (0.3.1)
Requirement already satisfied: dnspython<3.0.0,>=1.16.0 in /usr/local/lib/python3.8/dist-packages (from pymongo) (2.4.2)
Requirement already satisfied: tzdata>=2022.1 in /usr/local/lib/python3.8/dist-packages (from pandas) (2023.3)
Requirement already satisfied: numpy>=1.20.3; python_version < "3.10" in /usr/local/lib/python3.8/dist-packages (from pandas) (1.24.4)
Requirement already satisfied: pytz>=2020.1 in /usr/local/lib/python3.8/dist-packages (from pandas) (2023.3.post1)
Requirement already satisfied: python-dateutil>=2.8.2 in /usr/local/lib/python3.8/dist-packages (from pandas) (2.8.2)
Requirement already satisfied: six>=1.5 in /usr/local/lib/python3.8/dist-packages (from python-dateutil>=2.8.2->pandas) (1.16.0)
Running /platform/source/s01/v4_engoff/m21212121/m21212121_q21_t0.sh
Running /platform/source/s01/v4_engoff/m21212121/m21212121_q22_t0.sh
/platform/source/s01/v4_engoff/m21212121/m21212121_q22_t0.sh: line 5: sudo: command not found
/platform/source/s01/v4_engoff/m21212121/m21212121_q22_t0.sh: line 6: sudo: command not found
Requirement already satisfied: pymongo in /usr/local/lib/python3.8/dist-packages (4.6.0)
Requirement already satisfied: dnspython<3.0.0,>=1.16.0 in /usr/local/lib/python3.8/dist-packages (from pymongo) (2.4.2)
Requirement already satisfied: pandas in /usr/local/lib/python3.8/dist-packages (2.0.3)
Requirement already satisfied: numpy>=1.20.3; python_version < "3.10" in /usr/local/lib/python3.8/dist-packages (from pandas) (1.24.4)
Requirement already satisfied: python-dateutil>=2.8.2 in /usr/local/lib/python3.8/dist-packages (from pandas) (2.8.2)
Requirement already satisfied: pytz>=2020.1 in /usr/local/lib/python3.8/dist-packages (from pandas) (2023.3.post1)
Requirement already satisfied: tzdata>=2022.1 in /usr/local/lib/python3.8/dist-packages (from pandas) (2023.3)
Requirement already satisfied: six>=1.5 in /usr/local/lib/python3.8/dist-packages (from python-dateutil>=2.8.2->pandas) (1.16.0)
Requirement already satisfied: direct_redis in /usr/local/lib/python3.8/dist-packages (0.3.1)
Requirement already satisfied: redis==3.4.1 in /usr/local/lib/python3.8/dist-packages (from direct_redis) (3.4.1)
Running /platform/source/s01/v4_engoff/m21212121/m21212121_q2_t0.sh
0% [Working]            Hit:1 http://ports.ubuntu.com/ubuntu-ports focal InRelease
0% [Working]            Hit:2 http://ports.ubuntu.com/ubuntu-ports focal-updates InRelease
0% [Waiting for headers]0% [Waiting for headers]0% [Waiting for headers]                        Hit:3 http://ports.ubuntu.com/ubuntu-ports focal-backports InRelease
                        0% [Working]0% [Waiting for headers]                        Hit:4 http://ports.ubuntu.com/ubuntu-ports focal-security InRelease
                        0% [Working]20% [Working]             Reading package lists... 0%Reading package lists... 0%Reading package lists... 0%Reading package lists... 6%Reading package lists... 6%Reading package lists... 6%Reading package lists... 6%Reading package lists... 60%Reading package lists... 60%Reading package lists... 61%Reading package lists... 61%Reading package lists... 74%Reading package lists... 74%Reading package lists... 75%Reading package lists... 75%Reading package lists... 81%Reading package lists... 81%Reading package lists... 81%Reading package lists... 81%Reading package lists... 82%Reading package lists... 82%Reading package lists... 82%Reading package lists... 82%Reading package lists... 94%Reading package lists... 94%Reading package lists... 94%Reading package lists... 94%Reading package lists... 99%Reading package lists... 99%Reading package lists... 99%Reading package lists... 99%Reading package lists... Done
Reading package lists... 0%Reading package lists... 0%Reading package lists... 0%Reading package lists... 6%Reading package lists... 6%Reading package lists... 6%Reading package lists... 6%Reading package lists... 60%Reading package lists... 60%Reading package lists... 61%Reading package lists... 61%Reading package lists... 74%Reading package lists... 74%Reading package lists... 75%Reading package lists... 75%Reading package lists... 81%Reading package lists... 81%Reading package lists... 81%Reading package lists... 81%Reading package lists... 82%Reading package lists... 82%Reading package lists... 82%Reading package lists... 82%Reading package lists... 94%Reading package lists... 94%Reading package lists... 94%Reading package lists... 94%Reading package lists... 99%Reading package lists... 99%Reading package lists... 99%Reading package lists... 99%Reading package lists... Done
Building dependency tree... 0%Building dependency tree... 0%Building dependency tree... 50%Building dependency tree... 50%Building dependency tree       
Reading state information... 0%Reading state information... 0%Reading state information... Done
python3 is already the newest version (3.8.2-0ubuntu2).
python3 set to manually installed.
python3-pip is already the newest version (20.0.2-5ubuntu1.10).
0 upgraded, 0 newly installed, 0 to remove and 0 not upgraded.
Requirement already satisfied: pymongo in /usr/local/lib/python3.8/dist-packages (4.6.0)
Requirement already satisfied: pandas in /usr/local/lib/python3.8/dist-packages (2.0.3)
Requirement already satisfied: direct_redis in /usr/local/lib/python3.8/dist-packages (0.3.1)
Requirement already satisfied: dnspython<3.0.0,>=1.16.0 in /usr/local/lib/python3.8/dist-packages (from pymongo) (2.4.2)
Requirement already satisfied: numpy>=1.20.3; python_version < "3.10" in /usr/local/lib/python3.8/dist-packages (from pandas) (1.24.4)
Requirement already satisfied: python-dateutil>=2.8.2 in /usr/local/lib/python3.8/dist-packages (from pandas) (2.8.2)
Requirement already satisfied: pytz>=2020.1 in /usr/local/lib/python3.8/dist-packages (from pandas) (2023.3.post1)
Requirement already satisfied: tzdata>=2022.1 in /usr/local/lib/python3.8/dist-packages (from pandas) (2023.3)
Requirement already satisfied: redis==3.4.1 in /usr/local/lib/python3.8/dist-packages (from direct_redis) (3.4.1)
Requirement already satisfied: six>=1.5 in /usr/local/lib/python3.8/dist-packages (from python-dateutil>=2.8.2->pandas) (1.16.0)
Running /platform/source/s01/v4_engoff/m21212121/m21212121_q3_t0.sh
0% [Working]            Hit:1 http://ports.ubuntu.com/ubuntu-ports focal InRelease
0% [Working]0% [Waiting for headers]                        Hit:2 http://ports.ubuntu.com/ubuntu-ports focal-updates InRelease
                        0% [Working]0% [Waiting for headers]                        Hit:3 http://ports.ubuntu.com/ubuntu-ports focal-backports InRelease
                        0% [Working]0% [Waiting for headers]                        Hit:4 http://ports.ubuntu.com/ubuntu-ports focal-security InRelease
                        0% [Working]20% [Working]             Reading package lists... 0%Reading package lists... 0%Reading package lists... 0%Reading package lists... 6%Reading package lists... 6%Reading package lists... 6%Reading package lists... 6%Reading package lists... 60%Reading package lists... 60%Reading package lists... 61%Reading package lists... 61%Reading package lists... 74%Reading package lists... 74%Reading package lists... 75%Reading package lists... 75%Reading package lists... 81%Reading package lists... 81%Reading package lists... 81%Reading package lists... 81%Reading package lists... 82%Reading package lists... 82%Reading package lists... 82%Reading package lists... 82%Reading package lists... 94%Reading package lists... 94%Reading package lists... 94%Reading package lists... 94%Reading package lists... 99%Reading package lists... 99%Reading package lists... 99%Reading package lists... 99%Reading package lists... Done
Reading package lists... 0%Reading package lists... 0%Reading package lists... 0%Reading package lists... 6%Reading package lists... 6%Reading package lists... 6%Reading package lists... 6%Reading package lists... 60%Reading package lists... 60%Reading package lists... 61%Reading package lists... 61%Reading package lists... 74%Reading package lists... 74%Reading package lists... 75%Reading package lists... 75%Reading package lists... 81%Reading package lists... 81%Reading package lists... 81%Reading package lists... 81%Reading package lists... 82%Reading package lists... 82%Reading package lists... 82%Reading package lists... 82%Reading package lists... 94%Reading package lists... 94%Reading package lists... 94%Reading package lists... 94%Reading package lists... 99%Reading package lists... 99%Reading package lists... 99%Reading package lists... 99%Reading package lists... Done
Building dependency tree... 0%Building dependency tree... 0%Building dependency tree... 50%Building dependency tree... 50%Building dependency tree       
Reading state information... 0%Reading state information... 0%Reading state information... Done
python3-pip is already the newest version (20.0.2-5ubuntu1.10).
0 upgraded, 0 newly installed, 0 to remove and 0 not upgraded.
Requirement already satisfied: pymongo in /usr/local/lib/python3.8/dist-packages (4.6.0)
Requirement already satisfied: dnspython<3.0.0,>=1.16.0 in /usr/local/lib/python3.8/dist-packages (from pymongo) (2.4.2)
Collecting git+https://github.com/RedisLabsModules/redis-py.git
  Cloning https://github.com/RedisLabsModules/redis-py.git to /tmp/pip-req-build-hly4roxo
  Running command git clone -q https://github.com/RedisLabsModules/redis-py.git /tmp/pip-req-build-hly4roxo
[31m  ERROR: Error [Errno 2] No such file or directory: 'git' while executing command git clone -q https://github.com/RedisLabsModules/redis-py.git /tmp/pip-req-build-hly4roxo[0m
[31mERROR: Cannot find command 'git' - do you have 'git' installed and in your PATH?[0m
Requirement already satisfied: pandas in /usr/local/lib/python3.8/dist-packages (2.0.3)
Requirement already satisfied: pytz>=2020.1 in /usr/local/lib/python3.8/dist-packages (from pandas) (2023.3.post1)
Requirement already satisfied: python-dateutil>=2.8.2 in /usr/local/lib/python3.8/dist-packages (from pandas) (2.8.2)
Requirement already satisfied: tzdata>=2022.1 in /usr/local/lib/python3.8/dist-packages (from pandas) (2023.3)
Requirement already satisfied: numpy>=1.20.3; python_version < "3.10" in /usr/local/lib/python3.8/dist-packages (from pandas) (1.24.4)
Requirement already satisfied: six>=1.5 in /usr/local/lib/python3.8/dist-packages (from python-dateutil>=2.8.2->pandas) (1.16.0)
Running /platform/source/s01/v4_engoff/m21212121/m21212121_q4_t0.sh
/platform/source/s01/v4_engoff/m21212121/m21212121_q4_t0.sh: line 4: sudo: command not found
/platform/source/s01/v4_engoff/m21212121/m21212121_q4_t0.sh: line 5: sudo: command not found
Requirement already satisfied: pymongo in /usr/local/lib/python3.8/dist-packages (4.6.0)
Requirement already satisfied: dnspython<3.0.0,>=1.16.0 in /usr/local/lib/python3.8/dist-packages (from pymongo) (2.4.2)
Requirement already satisfied: pandas in /usr/local/lib/python3.8/dist-packages (2.0.3)
Requirement already satisfied: python-dateutil>=2.8.2 in /usr/local/lib/python3.8/dist-packages (from pandas) (2.8.2)
Requirement already satisfied: pytz>=2020.1 in /usr/local/lib/python3.8/dist-packages (from pandas) (2023.3.post1)
Requirement already satisfied: numpy>=1.20.3; python_version < "3.10" in /usr/local/lib/python3.8/dist-packages (from pandas) (1.24.4)
Requirement already satisfied: tzdata>=2022.1 in /usr/local/lib/python3.8/dist-packages (from pandas) (2023.3)
Requirement already satisfied: six>=1.5 in /usr/local/lib/python3.8/dist-packages (from python-dateutil>=2.8.2->pandas) (1.16.0)
Requirement already satisfied: direct_redis in /usr/local/lib/python3.8/dist-packages (0.3.1)
Requirement already satisfied: redis==3.4.1 in /usr/local/lib/python3.8/dist-packages (from direct_redis) (3.4.1)
Running /platform/source/s01/v4_engoff/m21212121/m21212121_q5_t0.sh
/platform/source/s01/v4_engoff/m21212121/m21212121_q5_t0.sh: line 4: sudo: command not found
/platform/source/s01/v4_engoff/m21212121/m21212121_q5_t0.sh: line 7: sudo: command not found
Requirement already satisfied: pandas in /usr/local/lib/python3.8/dist-packages (2.0.3)
Requirement already satisfied: pymongo in /usr/local/lib/python3.8/dist-packages (4.6.0)
Requirement already satisfied: direct_redis in /usr/local/lib/python3.8/dist-packages (0.3.1)
Requirement already satisfied: tzdata>=2022.1 in /usr/local/lib/python3.8/dist-packages (from pandas) (2023.3)
Requirement already satisfied: python-dateutil>=2.8.2 in /usr/local/lib/python3.8/dist-packages (from pandas) (2.8.2)
Requirement already satisfied: numpy>=1.20.3; python_version < "3.10" in /usr/local/lib/python3.8/dist-packages (from pandas) (1.24.4)
Requirement already satisfied: pytz>=2020.1 in /usr/local/lib/python3.8/dist-packages (from pandas) (2023.3.post1)
Requirement already satisfied: dnspython<3.0.0,>=1.16.0 in /usr/local/lib/python3.8/dist-packages (from pymongo) (2.4.2)
Requirement already satisfied: redis==3.4.1 in /usr/local/lib/python3.8/dist-packages (from direct_redis) (3.4.1)
Requirement already satisfied: six>=1.5 in /usr/local/lib/python3.8/dist-packages (from python-dateutil>=2.8.2->pandas) (1.16.0)
Running /platform/source/s01/v4_engoff/m21212121/m21212121_q6_t0.sh
/platform/source/s01/v4_engoff/m21212121/m21212121_q6_t0.sh: line 4: sudo: command not found
/platform/source/s01/v4_engoff/m21212121/m21212121_q6_t0.sh: line 5: sudo: command not found
Requirement already satisfied: pymongo in /usr/local/lib/python3.8/dist-packages (4.6.0)
Requirement already satisfied: dnspython<3.0.0,>=1.16.0 in /usr/local/lib/python3.8/dist-packages (from pymongo) (2.4.2)
Running /platform/source/s01/v4_engoff/m21212121/m21212121_q7_t0.sh
The virtual environment was not created successfully because ensurepip is not
available.  On Debian/Ubuntu systems, you need to install the python3-venv
package using the following command.

    apt install python3.8-venv

You may need to use sudo with that command.  After installing the python3-venv
package, recreate your virtual environment.

Failing command: ['/venv/bin/python3', '-Im', 'ensurepip', '--upgrade', '--default-pip']

/platform/source/s01/v4_engoff/m21212121/m21212121_q7_t0.sh: line 5: venv/bin/activate: No such file or directory
Requirement already satisfied: pymongo in /usr/local/lib/python3.8/dist-packages (4.6.0)
Requirement already satisfied: pandas in /usr/local/lib/python3.8/dist-packages (2.0.3)
Requirement already satisfied: direct-redis in /usr/local/lib/python3.8/dist-packages (0.3.1)
Requirement already satisfied: dnspython<3.0.0,>=1.16.0 in /usr/local/lib/python3.8/dist-packages (from pymongo) (2.4.2)
Requirement already satisfied: pytz>=2020.1 in /usr/local/lib/python3.8/dist-packages (from pandas) (2023.3.post1)
Requirement already satisfied: numpy>=1.20.3; python_version < "3.10" in /usr/local/lib/python3.8/dist-packages (from pandas) (1.24.4)
Requirement already satisfied: tzdata>=2022.1 in /usr/local/lib/python3.8/dist-packages (from pandas) (2023.3)
Requirement already satisfied: python-dateutil>=2.8.2 in /usr/local/lib/python3.8/dist-packages (from pandas) (2.8.2)
Requirement already satisfied: redis==3.4.1 in /usr/local/lib/python3.8/dist-packages (from direct-redis) (3.4.1)
Requirement already satisfied: six>=1.5 in /usr/local/lib/python3.8/dist-packages (from python-dateutil>=2.8.2->pandas) (1.16.0)
/platform/source/s01/v4_engoff/m21212121/m21212121_q7_t0.sh: line 11: deactivate: command not found
Running /platform/source/s01/v4_engoff/m21212121/m21212121_q8_t0.sh
/platform/source/s01/v4_engoff/m21212121/m21212121_q8_t0.sh: line 6: sudo: command not found
/platform/source/s01/v4_engoff/m21212121/m21212121_q8_t0.sh: line 9: sudo: command not found
/platform/source/s01/v4_engoff/m21212121/m21212121_q8_t0.sh: line 10: sudo: command not found
Requirement already satisfied: pymongo in /usr/local/lib/python3.8/dist-packages (4.6.0)
Requirement already satisfied: pandas in /usr/local/lib/python3.8/dist-packages (2.0.3)
Requirement already satisfied: redis in /usr/local/lib/python3.8/dist-packages (3.4.1)
Requirement already satisfied: dnspython<3.0.0,>=1.16.0 in /usr/local/lib/python3.8/dist-packages (from pymongo) (2.4.2)
Requirement already satisfied: pytz>=2020.1 in /usr/local/lib/python3.8/dist-packages (from pandas) (2023.3.post1)
Requirement already satisfied: python-dateutil>=2.8.2 in /usr/local/lib/python3.8/dist-packages (from pandas) (2.8.2)
Requirement already satisfied: numpy>=1.20.3; python_version < "3.10" in /usr/local/lib/python3.8/dist-packages (from pandas) (1.24.4)
Requirement already satisfied: tzdata>=2022.1 in /usr/local/lib/python3.8/dist-packages (from pandas) (2023.3)
Requirement already satisfied: six>=1.5 in /usr/local/lib/python3.8/dist-packages (from python-dateutil>=2.8.2->pandas) (1.16.0)
Running /platform/source/s01/v4_engoff/m21212121/m21212121_q9_t0.sh
/platform/source/s01/v4_engoff/m21212121/m21212121_q9_t0.sh: line 4: sudo: command not found
/platform/source/s01/v4_engoff/m21212121/m21212121_q9_t0.sh: line 5: sudo: command not found
Requirement already satisfied: pymongo in /usr/local/lib/python3.8/dist-packages (4.6.0)
Requirement already satisfied: pandas in /usr/local/lib/python3.8/dist-packages (2.0.3)
Requirement already satisfied: redis in /usr/local/lib/python3.8/dist-packages (3.4.1)
Requirement already satisfied: direct_redis in /usr/local/lib/python3.8/dist-packages (0.3.1)
Requirement already satisfied: dnspython<3.0.0,>=1.16.0 in /usr/local/lib/python3.8/dist-packages (from pymongo) (2.4.2)
Requirement already satisfied: tzdata>=2022.1 in /usr/local/lib/python3.8/dist-packages (from pandas) (2023.3)
Requirement already satisfied: numpy>=1.20.3; python_version < "3.10" in /usr/local/lib/python3.8/dist-packages (from pandas) (1.24.4)
Requirement already satisfied: python-dateutil>=2.8.2 in /usr/local/lib/python3.8/dist-packages (from pandas) (2.8.2)
Requirement already satisfied: pytz>=2020.1 in /usr/local/lib/python3.8/dist-packages (from pandas) (2023.3.post1)
Requirement already satisfied: six>=1.5 in /usr/local/lib/python3.8/dist-packages (from python-dateutil>=2.8.2->pandas) (1.16.0)
python /dbknitter/dbknitter/grader.py /platform/source/s01/v4_engoff/m21212121/m21212121_q10_t0.py /platform/output/s01/v4_engoff/m21212121/m21212121_q10_t0.csv /platform/expected/s01/q10.csv
Traceback (most recent call last):
  File "/platform/source/s01/v4_engoff/m21212121/m21212121_q10_t0.py", line 18, in <module>
    nation_df = pd.read_json(nation_data)
  File "/usr/local/lib/python3.8/dist-packages/pandas/io/json/_json.py", line 760, in read_json
    json_reader = JsonReader(
  File "/usr/local/lib/python3.8/dist-packages/pandas/io/json/_json.py", line 861, in __init__
    data = self._get_data_from_filepath(filepath_or_buffer)
  File "/usr/local/lib/python3.8/dist-packages/pandas/io/json/_json.py", line 901, in _get_data_from_filepath
    self.handles = get_handle(
  File "/usr/local/lib/python3.8/dist-packages/pandas/io/common.py", line 707, in get_handle
    if _is_binary_mode(path_or_buf, mode) and "b" not in mode:
  File "/usr/local/lib/python3.8/dist-packages/pandas/io/common.py", line 1167, in _is_binary_mode
    return isinstance(handle, _get_binary_io_classes()) or "b" in getattr(
TypeError: argument of type 'method' is not iterable
Score.fail_execute
python /dbknitter/dbknitter/grader.py /platform/source/s01/v4_engoff/m21212121/m21212121_q11_t0.py /platform/output/s01/v4_engoff/m21212121/m21212121_q11_t0.csv /platform/expected/s01/q11.csv
Traceback (most recent call last):
  File "/platform/source/s01/v4_engoff/m21212121/m21212121_q11_t0.py", line 20, in <module>
    nation_df = pd.read_json(redis_client.get('nation').decode('utf-8'))
  File "/usr/local/lib/python3.8/dist-packages/pandas/core/generic.py", line 5989, in __getattr__
    return object.__getattribute__(self, name)
AttributeError: 'DataFrame' object has no attribute 'decode'
Score.fail_execute
python /dbknitter/dbknitter/grader.py /platform/source/s01/v4_engoff/m21212121/m21212121_q12_t0.py /platform/output/s01/v4_engoff/m21212121/m21212121_q12_t0.csv /platform/expected/s01/q12.csv
Traceback (most recent call last):
  File "/platform/source/s01/v4_engoff/m21212121/m21212121_q12_t0.py", line 16, in <module>
    orders_df = pd.read_json(orders_data)
  File "/usr/local/lib/python3.8/dist-packages/pandas/io/json/_json.py", line 760, in read_json
    json_reader = JsonReader(
  File "/usr/local/lib/python3.8/dist-packages/pandas/io/json/_json.py", line 861, in __init__
    data = self._get_data_from_filepath(filepath_or_buffer)
  File "/usr/local/lib/python3.8/dist-packages/pandas/io/json/_json.py", line 901, in _get_data_from_filepath
    self.handles = get_handle(
  File "/usr/local/lib/python3.8/dist-packages/pandas/io/common.py", line 707, in get_handle
    if _is_binary_mode(path_or_buf, mode) and "b" not in mode:
  File "/usr/local/lib/python3.8/dist-packages/pandas/io/common.py", line 1167, in _is_binary_mode
    return isinstance(handle, _get_binary_io_classes()) or "b" in getattr(
TypeError: argument of type 'method' is not iterable
Score.fail_execute
python /dbknitter/dbknitter/grader.py /platform/source/s01/v4_engoff/m21212121/m21212121_q13_t0.py /platform/output/s01/v4_engoff/m21212121/m21212121_q13_t0.csv /platform/expected/s01/q13.csv
Traceback (most recent call last):
  File "/platform/source/s01/v4_engoff/m21212121/m21212121_q13_t0.py", line 21, in <module>
    orders_df = pd.read_json(orders_data, orient='records')
  File "/usr/local/lib/python3.8/dist-packages/pandas/io/json/_json.py", line 760, in read_json
    json_reader = JsonReader(
  File "/usr/local/lib/python3.8/dist-packages/pandas/io/json/_json.py", line 861, in __init__
    data = self._get_data_from_filepath(filepath_or_buffer)
  File "/usr/local/lib/python3.8/dist-packages/pandas/io/json/_json.py", line 901, in _get_data_from_filepath
    self.handles = get_handle(
  File "/usr/local/lib/python3.8/dist-packages/pandas/io/common.py", line 707, in get_handle
    if _is_binary_mode(path_or_buf, mode) and "b" not in mode:
  File "/usr/local/lib/python3.8/dist-packages/pandas/io/common.py", line 1167, in _is_binary_mode
    return isinstance(handle, _get_binary_io_classes()) or "b" in getattr(
TypeError: argument of type 'method' is not iterable
Score.fail_execute
python /dbknitter/dbknitter/grader.py /platform/source/s01/v4_engoff/m21212121/m21212121_q14_t0.py /platform/output/s01/v4_engoff/m21212121/m21212121_q14_t0.csv /platform/expected/s01/q14.csv
Traceback (most recent call last):
  File "/platform/source/s01/v4_engoff/m21212121/m21212121_q14_t0.py", line 30, in <module>
    part_df = pd.read_json(part_data)
  File "/usr/local/lib/python3.8/dist-packages/pandas/io/json/_json.py", line 760, in read_json
    json_reader = JsonReader(
  File "/usr/local/lib/python3.8/dist-packages/pandas/io/json/_json.py", line 861, in __init__
    data = self._get_data_from_filepath(filepath_or_buffer)
  File "/usr/local/lib/python3.8/dist-packages/pandas/io/json/_json.py", line 901, in _get_data_from_filepath
    self.handles = get_handle(
  File "/usr/local/lib/python3.8/dist-packages/pandas/io/common.py", line 707, in get_handle
    if _is_binary_mode(path_or_buf, mode) and "b" not in mode:
  File "/usr/local/lib/python3.8/dist-packages/pandas/io/common.py", line 1167, in _is_binary_mode
    return isinstance(handle, _get_binary_io_classes()) or "b" in getattr(
TypeError: argument of type 'method' is not iterable
Score.fail_execute
python /dbknitter/dbknitter/grader.py /platform/source/s01/v4_engoff/m21212121/m21212121_q15_t0.py /platform/output/s01/v4_engoff/m21212121/m21212121_q15_t0.csv /platform/expected/s01/q15.csv
>>> Expected ((1, 5))
               S_ADDRESS              S_NAME          S_PHONE  S_SUPPKEY  TOTAL_REVENUE
0  8mhrffG7D2WJBSQbOGstQ  Supplier#000000677  23-290-639-3315        677   1.614410e+06

>>> Actual ((0, 8))
Empty DataFrame
Columns: [S_ACCTBAL, S_ADDRESS, S_COMMENT, S_NAME, S_NATIONKEY, S_PHONE, S_SUPPKEY, total_revenue]
Index: []

Score.fail_wrong_output
python /dbknitter/dbknitter/grader.py /platform/source/s01/v4_engoff/m21212121/m21212121_q16_t0.py /platform/output/s01/v4_engoff/m21212121/m21212121_q16_t0.csv /platform/expected/s01/q16.csv
Traceback (most recent call last):
  File "/platform/source/s01/v4_engoff/m21212121/m21212121_q16_t0.py", line 19, in <module>
    parts_df = pd.read_json(redis.get('part'))  # Redis should return data as a JSON string
  File "/usr/local/lib/python3.8/dist-packages/pandas/io/json/_json.py", line 760, in read_json
    json_reader = JsonReader(
  File "/usr/local/lib/python3.8/dist-packages/pandas/io/json/_json.py", line 861, in __init__
    data = self._get_data_from_filepath(filepath_or_buffer)
  File "/usr/local/lib/python3.8/dist-packages/pandas/io/json/_json.py", line 901, in _get_data_from_filepath
    self.handles = get_handle(
  File "/usr/local/lib/python3.8/dist-packages/pandas/io/common.py", line 707, in get_handle
    if _is_binary_mode(path_or_buf, mode) and "b" not in mode:
  File "/usr/local/lib/python3.8/dist-packages/pandas/io/common.py", line 1167, in _is_binary_mode
    return isinstance(handle, _get_binary_io_classes()) or "b" in getattr(
TypeError: argument of type 'method' is not iterable
Score.fail_execute
python /dbknitter/dbknitter/grader.py /platform/source/s01/v4_engoff/m21212121/m21212121_q17_t0.py /platform/output/s01/v4_engoff/m21212121/m21212121_q17_t0.csv /platform/expected/s01/q17.csv
Traceback (most recent call last):
  File "/platform/source/s01/v4_engoff/m21212121/m21212121_q17_t0.py", line 26, in <module>
    part_df = pd.read_json(part_str, orient='records')
  File "/usr/local/lib/python3.8/dist-packages/pandas/io/json/_json.py", line 760, in read_json
    json_reader = JsonReader(
  File "/usr/local/lib/python3.8/dist-packages/pandas/io/json/_json.py", line 861, in __init__
    data = self._get_data_from_filepath(filepath_or_buffer)
  File "/usr/local/lib/python3.8/dist-packages/pandas/io/json/_json.py", line 901, in _get_data_from_filepath
    self.handles = get_handle(
  File "/usr/local/lib/python3.8/dist-packages/pandas/io/common.py", line 707, in get_handle
    if _is_binary_mode(path_or_buf, mode) and "b" not in mode:
  File "/usr/local/lib/python3.8/dist-packages/pandas/io/common.py", line 1167, in _is_binary_mode
    return isinstance(handle, _get_binary_io_classes()) or "b" in getattr(
TypeError: argument of type 'method' is not iterable
Score.fail_execute
python /dbknitter/dbknitter/grader.py /platform/source/s01/v4_engoff/m21212121/m21212121_q18_t0.py /platform/output/s01/v4_engoff/m21212121/m21212121_q18_t0.csv /platform/expected/s01/q18.csv
Traceback (most recent call last):
  File "/platform/source/s01/v4_engoff/m21212121/m21212121_q18_t0.py", line 26, in <module>
    orders = redis_client.get('orders')
  File "/usr/local/lib/python3.8/dist-packages/redis/client.py", line 1579, in get
    return self.execute_command('GET', name)
  File "/usr/local/lib/python3.8/dist-packages/redis/client.py", line 878, in execute_command
    return self.parse_response(conn, command_name, **options)
  File "/usr/local/lib/python3.8/dist-packages/redis/client.py", line 892, in parse_response
    response = connection.read_response()
  File "/usr/local/lib/python3.8/dist-packages/redis/connection.py", line 734, in read_response
    response = self._parser.read_response()
  File "/usr/local/lib/python3.8/dist-packages/redis/connection.py", line 358, in read_response
    response = self.encoder.decode(response)
  File "/usr/local/lib/python3.8/dist-packages/redis/connection.py", line 129, in decode
    value = value.decode(self.encoding, self.encoding_errors)
UnicodeDecodeError: 'utf-8' codec can't decode byte 0x80 in position 0: invalid start byte
Score.fail_execute
python /dbknitter/dbknitter/grader.py /platform/source/s01/v4_engoff/m21212121/m21212121_q19_t0.py /platform/output/s01/v4_engoff/m21212121/m21212121_q19_t0.csv /platform/expected/s01/q19.csv
Traceback (most recent call last):
  File "/platform/source/s01/v4_engoff/m21212121/m21212121_q19_t0.py", line 33, in <module>
    part_data = pd.read_json(redis_client.get('part'))
  File "/usr/local/lib/python3.8/dist-packages/pandas/io/json/_json.py", line 760, in read_json
    json_reader = JsonReader(
  File "/usr/local/lib/python3.8/dist-packages/pandas/io/json/_json.py", line 861, in __init__
    data = self._get_data_from_filepath(filepath_or_buffer)
  File "/usr/local/lib/python3.8/dist-packages/pandas/io/json/_json.py", line 901, in _get_data_from_filepath
    self.handles = get_handle(
  File "/usr/local/lib/python3.8/dist-packages/pandas/io/common.py", line 707, in get_handle
    if _is_binary_mode(path_or_buf, mode) and "b" not in mode:
  File "/usr/local/lib/python3.8/dist-packages/pandas/io/common.py", line 1167, in _is_binary_mode
    return isinstance(handle, _get_binary_io_classes()) or "b" in getattr(
TypeError: argument of type 'method' is not iterable
Score.fail_execute
python /dbknitter/dbknitter/grader.py /platform/source/s01/v4_engoff/m21212121/m21212121_q1_t0.py /platform/output/s01/v4_engoff/m21212121/m21212121_q1_t0.csv /platform/expected/s01/q1.csv
>>> Expected ((4, 10))
   AVG_DISC     AVG_PRICE    AVG_QTY  COUNT_ORDER L_LINESTATUS L_RETURNFLAG  SUM_BASE_PRICE    SUM_CHARGE  SUM_DISC_PRICE  SUM_QTY
0  0.050145  36002.123829  25.537587       147790            F            A    5.320754e+09  5.256751e+09    5.054096e+09  3774200
1  0.049394  35521.326916  25.300664         3765            F            N    1.337378e+08  1.322863e+08    1.271324e+08    95257
2  0.050096  36000.924688  25.545538       292000            O            N    1.051227e+10  1.038558e+10    9.986238e+09  7459297
3  0.049989  35994.029214  25.525944       148301            F            R    5.337951e+09  5.274406e+09    5.071819e+09  3785523

>>> Actual ((0, 10))
Empty DataFrame
Columns: [AVERAGE_DISCOUNT, AVERAGE_EXTENDEDPRICE, AVERAGE_QUANTITY, CHARGE, COUNT_ORDER, DISC_PRICE, EXTENDEDPRICE, LINESTATUS, QUANTITY, RETURNFLAG]
Index: []

Score.fail_wrong_output
python /dbknitter/dbknitter/grader.py /platform/source/s01/v4_engoff/m21212121/m21212121_q20_t0.py /platform/output/s01/v4_engoff/m21212121/m21212121_q20_t0.csv /platform/expected/s01/q20.csv
Traceback (most recent call last):
  File "/platform/source/s01/v4_engoff/m21212121/m21212121_q20_t0.py", line 23, in <module>
    nation_df = pd.read_json(redis.get('nation'), orient='index')
  File "/usr/local/lib/python3.8/dist-packages/pandas/io/json/_json.py", line 760, in read_json
    json_reader = JsonReader(
  File "/usr/local/lib/python3.8/dist-packages/pandas/io/json/_json.py", line 861, in __init__
    data = self._get_data_from_filepath(filepath_or_buffer)
  File "/usr/local/lib/python3.8/dist-packages/pandas/io/json/_json.py", line 901, in _get_data_from_filepath
    self.handles = get_handle(
  File "/usr/local/lib/python3.8/dist-packages/pandas/io/common.py", line 707, in get_handle
    if _is_binary_mode(path_or_buf, mode) and "b" not in mode:
  File "/usr/local/lib/python3.8/dist-packages/pandas/io/common.py", line 1167, in _is_binary_mode
    return isinstance(handle, _get_binary_io_classes()) or "b" in getattr(
TypeError: argument of type 'method' is not iterable
Score.fail_execute
python /dbknitter/dbknitter/grader.py /platform/source/s01/v4_engoff/m21212121/m21212121_q21_t0.py /platform/output/s01/v4_engoff/m21212121/m21212121_q21_t0.csv /platform/expected/s01/q21.csv
Traceback (most recent call last):
  File "/platform/source/s01/v4_engoff/m21212121/m21212121_q21_t0.py", line 14, in <module>
    nation_df = pd.read_json(redis_client.get('nation'), orient='records')
  File "/usr/local/lib/python3.8/dist-packages/pandas/io/json/_json.py", line 760, in read_json
    json_reader = JsonReader(
  File "/usr/local/lib/python3.8/dist-packages/pandas/io/json/_json.py", line 861, in __init__
    data = self._get_data_from_filepath(filepath_or_buffer)
  File "/usr/local/lib/python3.8/dist-packages/pandas/io/json/_json.py", line 901, in _get_data_from_filepath
    self.handles = get_handle(
  File "/usr/local/lib/python3.8/dist-packages/pandas/io/common.py", line 707, in get_handle
    if _is_binary_mode(path_or_buf, mode) and "b" not in mode:
  File "/usr/local/lib/python3.8/dist-packages/pandas/io/common.py", line 1167, in _is_binary_mode
    return isinstance(handle, _get_binary_io_classes()) or "b" in getattr(
TypeError: argument of type 'method' is not iterable
Score.fail_execute
python /dbknitter/dbknitter/grader.py /platform/source/s01/v4_engoff/m21212121/m21212121_q22_t0.py /platform/output/s01/v4_engoff/m21212121/m21212121_q22_t0.csv /platform/expected/s01/q22.csv
Traceback (most recent call last):
  File "/platform/source/s01/v4_engoff/m21212121/m21212121_q22_t0.py", line 26, in <module>
    orders_data = pd.read_json(orders_data_json, orient='split')
  File "/usr/local/lib/python3.8/dist-packages/pandas/io/json/_json.py", line 760, in read_json
    json_reader = JsonReader(
  File "/usr/local/lib/python3.8/dist-packages/pandas/io/json/_json.py", line 861, in __init__
    data = self._get_data_from_filepath(filepath_or_buffer)
  File "/usr/local/lib/python3.8/dist-packages/pandas/io/json/_json.py", line 901, in _get_data_from_filepath
    self.handles = get_handle(
  File "/usr/local/lib/python3.8/dist-packages/pandas/io/common.py", line 707, in get_handle
    if _is_binary_mode(path_or_buf, mode) and "b" not in mode:
  File "/usr/local/lib/python3.8/dist-packages/pandas/io/common.py", line 1167, in _is_binary_mode
    return isinstance(handle, _get_binary_io_classes()) or "b" in getattr(
TypeError: argument of type 'method' is not iterable
Score.fail_execute
python /dbknitter/dbknitter/grader.py /platform/source/s01/v4_engoff/m21212121/m21212121_q2_t0.py /platform/output/s01/v4_engoff/m21212121/m21212121_q2_t0.csv /platform/expected/s01/q2.csv
Traceback (most recent call last):
  File "/platform/source/s01/v4_engoff/m21212121/m21212121_q2_t0.py", line 24, in <module>
    nation = pd.read_json(r.get('nation'))
  File "/usr/local/lib/python3.8/dist-packages/pandas/io/json/_json.py", line 760, in read_json
    json_reader = JsonReader(
  File "/usr/local/lib/python3.8/dist-packages/pandas/io/json/_json.py", line 861, in __init__
    data = self._get_data_from_filepath(filepath_or_buffer)
  File "/usr/local/lib/python3.8/dist-packages/pandas/io/json/_json.py", line 901, in _get_data_from_filepath
    self.handles = get_handle(
  File "/usr/local/lib/python3.8/dist-packages/pandas/io/common.py", line 707, in get_handle
    if _is_binary_mode(path_or_buf, mode) and "b" not in mode:
  File "/usr/local/lib/python3.8/dist-packages/pandas/io/common.py", line 1167, in _is_binary_mode
    return isinstance(handle, _get_binary_io_classes()) or "b" in getattr(
TypeError: argument of type 'method' is not iterable
Score.fail_execute
python /dbknitter/dbknitter/grader.py /platform/source/s01/v4_engoff/m21212121/m21212121_q3_t0.py /platform/output/s01/v4_engoff/m21212121/m21212121_q3_t0.csv /platform/expected/s01/q3.csv
Traceback (most recent call last):
  File "/platform/source/s01/v4_engoff/m21212121/m21212121_q3_t0.py", line 63, in <module>
    main()
  File "/platform/source/s01/v4_engoff/m21212121/m21212121_q3_t0.py", line 60, in main
    shipping_priority_query(mongo_client, redis_client)
  File "/platform/source/s01/v4_engoff/m21212121/m21212121_q3_t0.py", line 27, in shipping_priority_query
    orders = get_redis_data(redis_client, 'orders')
  File "/platform/source/s01/v4_engoff/m21212121/m21212121_q3_t0.py", line 15, in get_redis_data
    return pd.read_json(data, orient='records')
  File "/usr/local/lib/python3.8/dist-packages/pandas/io/json/_json.py", line 760, in read_json
    json_reader = JsonReader(
  File "/usr/local/lib/python3.8/dist-packages/pandas/io/json/_json.py", line 861, in __init__
    data = self._get_data_from_filepath(filepath_or_buffer)
  File "/usr/local/lib/python3.8/dist-packages/pandas/io/json/_json.py", line 901, in _get_data_from_filepath
    self.handles = get_handle(
  File "/usr/local/lib/python3.8/dist-packages/pandas/io/common.py", line 707, in get_handle
    if _is_binary_mode(path_or_buf, mode) and "b" not in mode:
  File "/usr/local/lib/python3.8/dist-packages/pandas/io/common.py", line 1167, in _is_binary_mode
    return isinstance(handle, _get_binary_io_classes()) or "b" in getattr(
TypeError: argument of type 'method' is not iterable
Score.fail_execute
python /dbknitter/dbknitter/grader.py /platform/source/s01/v4_engoff/m21212121/m21212121_q4_t0.py /platform/output/s01/v4_engoff/m21212121/m21212121_q4_t0.csv /platform/expected/s01/q4.csv
Traceback (most recent call last):
  File "/platform/source/s01/v4_engoff/m21212121/m21212121_q4_t0.py", line 40, in <module>
    orders_df = pd.read_csv(pd.compat.StringIO(orders_str.decode("utf-8")))
AttributeError: module 'pandas.compat' has no attribute 'StringIO'
Score.fail_execute
python /dbknitter/dbknitter/grader.py /platform/source/s01/v4_engoff/m21212121/m21212121_q5_t0.py /platform/output/s01/v4_engoff/m21212121/m21212121_q5_t0.csv /platform/expected/s01/q5.csv
Traceback (most recent call last):
  File "/platform/source/s01/v4_engoff/m21212121/m21212121_q5_t0.py", line 25, in <module>
    nation = pd.read_json(redis_client.get('nation'))
  File "/usr/local/lib/python3.8/dist-packages/pandas/io/json/_json.py", line 760, in read_json
    json_reader = JsonReader(
  File "/usr/local/lib/python3.8/dist-packages/pandas/io/json/_json.py", line 861, in __init__
    data = self._get_data_from_filepath(filepath_or_buffer)
  File "/usr/local/lib/python3.8/dist-packages/pandas/io/json/_json.py", line 901, in _get_data_from_filepath
    self.handles = get_handle(
  File "/usr/local/lib/python3.8/dist-packages/pandas/io/common.py", line 707, in get_handle
    if _is_binary_mode(path_or_buf, mode) and "b" not in mode:
  File "/usr/local/lib/python3.8/dist-packages/pandas/io/common.py", line 1167, in _is_binary_mode
    return isinstance(handle, _get_binary_io_classes()) or "b" in getattr(
TypeError: argument of type 'method' is not iterable
Score.fail_execute
python /dbknitter/dbknitter/grader.py /platform/source/s01/v4_engoff/m21212121/m21212121_q6_t0.py /platform/output/s01/v4_engoff/m21212121/m21212121_q6_t0.csv /platform/expected/s01/q6.csv
No columns to parse from file
Score.fail_parsing_output
python /dbknitter/dbknitter/grader.py /platform/source/s01/v4_engoff/m21212121/m21212121_q7_t0.py /platform/output/s01/v4_engoff/m21212121/m21212121_q7_t0.csv /platform/expected/s01/q7.csv
Traceback (most recent call last):
  File "/platform/source/s01/v4_engoff/m21212121/m21212121_q7_t0.py", line 14, in <module>
    nation = pd.read_json(r.get('nation'))
  File "/usr/local/lib/python3.8/dist-packages/pandas/io/json/_json.py", line 760, in read_json
    json_reader = JsonReader(
  File "/usr/local/lib/python3.8/dist-packages/pandas/io/json/_json.py", line 861, in __init__
    data = self._get_data_from_filepath(filepath_or_buffer)
  File "/usr/local/lib/python3.8/dist-packages/pandas/io/json/_json.py", line 901, in _get_data_from_filepath
    self.handles = get_handle(
  File "/usr/local/lib/python3.8/dist-packages/pandas/io/common.py", line 707, in get_handle
    if _is_binary_mode(path_or_buf, mode) and "b" not in mode:
  File "/usr/local/lib/python3.8/dist-packages/pandas/io/common.py", line 1167, in _is_binary_mode
    return isinstance(handle, _get_binary_io_classes()) or "b" in getattr(
TypeError: argument of type 'method' is not iterable
Score.fail_execute
python /dbknitter/dbknitter/grader.py /platform/source/s01/v4_engoff/m21212121/m21212121_q8_t0.py /platform/output/s01/v4_engoff/m21212121/m21212121_q8_t0.csv /platform/expected/s01/q8.csv
Traceback (most recent call last):
  File "/platform/source/s01/v4_engoff/m21212121/m21212121_q8_t0.py", line 65, in <module>
    main()
  File "/platform/source/s01/v4_engoff/m21212121/m21212121_q8_t0.py", line 33, in main
    nations_df = pd.DataFrame(redis_client.hgetall('nation'))
  File "/usr/local/lib/python3.8/dist-packages/direct_redis/direct_redis.py", line 63, in hgetall
    encoded = super().hgetall(name)
  File "/usr/local/lib/python3.8/dist-packages/redis/client.py", line 2979, in hgetall
    return self.execute_command('HGETALL', name)
  File "/usr/local/lib/python3.8/dist-packages/redis/client.py", line 878, in execute_command
    return self.parse_response(conn, command_name, **options)
  File "/usr/local/lib/python3.8/dist-packages/redis/client.py", line 892, in parse_response
    response = connection.read_response()
  File "/usr/local/lib/python3.8/dist-packages/redis/connection.py", line 752, in read_response
    raise response
redis.exceptions.ResponseError: WRONGTYPE Operation against a key holding the wrong kind of value
Score.fail_execute
python /dbknitter/dbknitter/grader.py /platform/source/s01/v4_engoff/m21212121/m21212121_q9_t0.py /platform/output/s01/v4_engoff/m21212121/m21212121_q9_t0.csv /platform/expected/s01/q9.csv
Traceback (most recent call last):
  File "/platform/source/s01/v4_engoff/m21212121/m21212121_q9_t0.py", line 21, in <module>
    nation_df = pd.read_json(redis_client.get('nation'), orient="records")
  File "/usr/local/lib/python3.8/dist-packages/pandas/io/json/_json.py", line 760, in read_json
    json_reader = JsonReader(
  File "/usr/local/lib/python3.8/dist-packages/pandas/io/json/_json.py", line 861, in __init__
    data = self._get_data_from_filepath(filepath_or_buffer)
  File "/usr/local/lib/python3.8/dist-packages/pandas/io/json/_json.py", line 901, in _get_data_from_filepath
    self.handles = get_handle(
  File "/usr/local/lib/python3.8/dist-packages/pandas/io/common.py", line 707, in get_handle
    if _is_binary_mode(path_or_buf, mode) and "b" not in mode:
  File "/usr/local/lib/python3.8/dist-packages/pandas/io/common.py", line 1167, in _is_binary_mode
    return isinstance(handle, _get_binary_io_classes()) or "b" in getattr(
TypeError: argument of type 'method' is not iterable
Score.fail_execute
